<mujoco model="v1.1_u3.0_0303_v0_29dof">
  <compiler angle="radian" meshdir="../urdf/meshes/"/>
  <default>
    <joint damping="0.001" armature="0.01" frictionloss="0.1"/> 
  </default>
  <asset>
    <mesh name="base_link" content_type="model/stl" file="base_link.STL"/>
    <mesh name="left_hip_pitch_link" content_type="model/stl" file="left_hip_pitch_link.STL"/>
    <mesh name="left_hip_roll_link" content_type="model/stl" file="left_hip_roll_link.STL"/>
    <mesh name="left_hip_yaw_link" content_type="model/stl" file="left_hip_yaw_link.STL"/>
    <mesh name="left_knee_link" content_type="model/stl" file="left_knee_link.STL"/>
    <mesh name="left_ankle_pitch_link" content_type="model/stl" file="left_ankle_pitch_link.STL"/>
    <mesh name="left_ankle_roll_link" content_type="model/stl" file="left_ankle_roll_link.STL"/>
    <mesh name="right_hip_pitch_link" content_type="model/stl" file="right_hip_pitch_link.STL"/>
    <mesh name="right_hip_roll_link" content_type="model/stl" file="right_hip_roll_link.STL"/>
    <mesh name="right_hip_yaw_link" content_type="model/stl" file="right_hip_yaw_link.STL"/>
    <mesh name="right_knee_link" content_type="model/stl" file="right_knee_link.STL"/>
    <mesh name="right_ankle_pitch_link" content_type="model/stl" file="right_ankle_pitch_link.STL"/>
    <mesh name="right_ankle_roll_link" content_type="model/stl" file="right_ankle_roll_link.STL"/>
    <mesh name="waist_yaw_link" content_type="model/stl" file="waist_yaw_link.STL"/>
    <mesh name="waist_roll_link" content_type="model/stl" file="waist_roll_link.STL"/>
    <mesh name="waist_pitch_link" content_type="model/stl" file="waist_pitch_link.STL"/>
    <mesh name="head_yaw_link" content_type="model/stl" file="head_yaw_link.STL"/>
    <mesh name="head_pitch_link" content_type="model/stl" file="head_pitch_link.STL"/>
    <mesh name="left_shoulder_pitch_link" content_type="model/stl" file="left_shoulder_pitch_link.STL"/>
    <mesh name="left_shoulder_roll_link" content_type="model/stl" file="left_shoulder_roll_link.STL"/>
    <mesh name="left_shoulder_yaw_link" content_type="model/stl" file="left_shoulder_yaw_link.STL"/>
    <mesh name="left_elbow_link" content_type="model/stl" file="left_elbow_link.STL"/>
    <mesh name="left_wrist_roll_link" content_type="model/stl" file="left_wrist_roll_link.STL"/>
    <mesh name="left_wrist_yaw_link" content_type="model/stl" file="left_wrist_yaw_link.STL"/>
    <mesh name="left_wrist_pitch_link" content_type="model/stl" file="left_wrist_pitch_link.STL"/>
    <mesh name="left_hand_link" content_type="model/stl" file="left_hand_link.STL"/>
    <mesh name="right_shoulder_pitch_link" content_type="model/stl" file="right_shoulder_pitch_link.STL"/>
    <mesh name="right_shoulder_roll_link" content_type="model/stl" file="right_shoulder_roll_link.STL"/>
    <mesh name="right_shoulder_yaw_link" content_type="model/stl" file="right_shoulder_yaw_link.STL"/>
    <mesh name="right_elbow_link" content_type="model/stl" file="right_elbow_link.STL"/>
    <mesh name="right_wrist_roll_link" content_type="model/stl" file="right_wrist_roll_link.STL"/>
    <mesh name="right_wrist_yaw_link" content_type="model/stl" file="right_wrist_yaw_link.STL"/>
    <mesh name="right_wrist_pitch_link" content_type="model/stl" file="right_wrist_pitch_link.STL"/>
    <mesh name="right_hand_link" content_type="model/stl" file="right_hand_link.STL"/>
  </asset>

  <worldbody>
    <body name="base_link" pos="0 0 0.87">
      <inertial pos="-0.000112 5e-06 -0.049468" quat="0.498239 0.498283 -0.501755 0.501711" mass="5.717" diaginertia="0.0303601 0.0283439 0.019181"/>
      <joint name="floating_base_joint" type="free" limited="false" actuatorfrclimited="false"/>
      <geom type="mesh" contype="0" conaffinity="0" group="1" density="0" rgba="0.75294 0.75294 0.75294 1" mesh="base_link"/>
      <geom size="0.05 0.1 0.025" pos="0 0 -0.04" type="box" rgba="0.75294 0.75294 0.75294 1"/>
      <site name="imu_in_pelvis" size="0.01" pos="-0.09835 0 -0.052"/>
      <body name="left_hip_pitch_link" pos="0 0.11619 -0.12455" quat="0.923879 -0.382684 0 0">
        <inertial pos="0.003887 0.021532 -0.028237" quat="0.870396 0.486242 -0.0312337 -0.0707405" mass="2.3165" diaginertia="0.00535112 0.00457582 0.00400306"/>
        <joint name="left_hip_pitch_joint" pos="0 0 0" axis="0 1 0" range="-2.618 2.618" actuatorfrcrange="-150 150"/>
        <geom type="mesh" contype="0" conaffinity="0" group="1" density="0" rgba="0.752941 0.752941 0.752941 1" mesh="left_hip_pitch_link"/>
        <!-- <geom size="0.055 0.055" pos="0 0.01 0" quat="0.707388 0.706825 0 0" type="cylinder" rgba="0.752941 0.752941 0.752941 1"/> -->
        <body name="left_hip_roll_link" pos="-0.001 0.03 -0.03" quat="0.923879 0.382684 0 0">
          <inertial pos="0.001502 2.7e-05 -0.084234" quat="0.62727 0.326393 0.326393 0.62727" mass="1.48" diaginertia="0.004535 0.00337114 0.00296686"/>
          <joint name="left_hip_roll_joint" pos="0 0 0" axis="1 0 0" range="-0.7854 2.3563" actuatorfrcrange="-150 150"/>
          <geom type="mesh" contype="0" conaffinity="0" group="1" density="0" rgba="0.752941 0.752941 0.752941 1" mesh="left_hip_roll_link"/>
          <geom size="0.07 0.025" pos="0 0 -0.09" type="cylinder" rgba="0.752941 0.752941 0.752941 1"/>
          <body name="left_hip_yaw_link" pos="0 0 -0.13">
            <inertial pos="-0.0107 -0.008795 -0.120268" quat="0.711829 0.00814217 0.0822562 0.697472" mass="2.325" diaginertia="0.00969146 0.00888604 0.00293651"/>
            <joint name="left_hip_yaw_joint" pos="0 0 0" axis="0 0 1" range="-2.0944 2.0944" actuatorfrcrange="-90 90"/>
            <geom type="mesh" contype="0" conaffinity="0" group="1" density="0" rgba="0.752941 0.752941 0.752941 1" mesh="left_hip_yaw_link"/>
            <geom type="mesh" rgba="0.752941 0.752941 0.752941 1" mesh="left_hip_yaw_link"/>
            <body name="left_knee_link" pos="-0.015 0 -0.151">
              <inertial pos="0.004163 0.000262 -0.138565" quat="0.99994 -0.00282969 -0.0106115 1.22531e-05" mass="1.83395" diaginertia="0.0104298 0.00990025 0.00194592"/>
              <joint name="left_knee_joint" pos="0 0 0" axis="0 1 0" range="-0.0873 2.0944" actuatorfrcrange="-150 150"/>
              <geom type="mesh" contype="0" conaffinity="0" group="1" density="0" rgba="0.752941 0.752941 0.752941 1" mesh="left_knee_link"/>
              <geom size="0.04 0.115" pos="0.01 0 -0.2" type="cylinder" rgba="0.752941 0.752941 0.752941 1"/>
              <body name="left_ankle_pitch_link" pos="0.015 0.0005 -0.339">
                <inertial pos="-0.002351 -0.000479 -0.006916" quat="0.344336 0.344336 -0.617602 0.617602" mass="0.102" diaginertia="2.22361e-05 1.77639e-05 1.7e-05"/>
                <joint name="left_ankle_pitch_joint" pos="0 0 0" axis="0 1 0" range="-0.9599 0.5218" actuatorfrcrange="-54 54"/>
                <geom type="mesh" contype="0" conaffinity="0" group="1" density="0" rgba="0.752941 0.752941 0.752941 1" mesh="left_ankle_pitch_link"/>
                <body name="left_ankle_roll_link" pos="0 0 -0.015">
                  <inertial pos="0.04469 -3.2e-05 -0.035309" quat="0.00358632 0.734652 0.00406875 0.678422" mass="0.968" diaginertia="0.00496359 0.00487899 0.000595419"/>
                  <joint name="left_ankle_roll_joint" pos="0 0 0" axis="1 0 0" range="-0.1745 0.1745" actuatorfrcrange="-54 54"/>
                  <geom type="mesh" contype="0" conaffinity="0" group="1" density="0" rgba="0.752941 0.752941 0.752941 1" mesh="left_ankle_roll_link"/>
                  <geom size="0.005" pos="-0.06 0.035 -0.06" rgba="0.752941 0.752941 0.752941 1"/>
                  <geom size="0.005" pos="-0.06 -0.035 -0.06" rgba="0.752941 0.752941 0.752941 1"/>
                  <geom size="0.005" pos="0.13 0.035 -0.06" rgba="0.752941 0.752941 0.752941 1"/>
                  <geom size="0.005" pos="0.13 -0.035 -0.06" rgba="0.752941 0.752941 0.752941 1"/>
                  <geom size="0.005" pos="0.17 0.018 -0.058" rgba="0.752941 0.752941 0.752941 1"/>
                  <geom size="0.005" pos="0.17 -0.018 -0.058" rgba="0.752941 0.752941 0.752941 1"/>
                  <geom size="0.005" pos="-0.035 0.035 -0.06" rgba="0.752941 0.752941 0.752941 1"/>
                  <geom size="0.005" pos="-0.035 -0.035 -0.06" rgba="0.752941 0.752941 0.752941 1"/>
                  <geom size="0.005" pos="0.06 0.035 -0.06" rgba="0.752941 0.752941 0.752941 1"/>
                  <geom size="0.005" pos="0.06 -0.035 -0.06" rgba="0.752941 0.752941 0.752941 1"/>
                </body>
              </body>
            </body>
          </body>
        </body>
      </body>
      <body name="right_hip_pitch_link" pos="0 -0.11619 -0.12455" quat="0.923879 0.382684 0 0">
        <inertial pos="0.003887 -0.021532 -0.028237" quat="0.486242 0.870396 0.0707405 0.0312337" mass="2.3165" diaginertia="0.00535112 0.00457582 0.00400306"/>
        <joint name="right_hip_pitch_joint" pos="0 0 0" axis="0 1 0" range="-2.618 2.618" actuatorfrcrange="-150 150"/>
        <geom type="mesh" contype="0" conaffinity="0" group="1" density="0" rgba="0.752941 0.752941 0.752941 1" mesh="right_hip_pitch_link"/>
        <!-- <geom size="0.055 0.055" pos="0 -0.01 0" quat="0.707388 0.706825 0 0" type="cylinder" rgba="0.752941 0.752941 0.752941 1"/> -->
        <body name="right_hip_roll_link" pos="-0.001 -0.03 -0.03" quat="0.923879 -0.382684 0 0">
          <inertial pos="0.001502 -2.7e-05 -0.084234" quat="0.62727 0.326393 0.326393 0.62727" mass="1.48" diaginertia="0.004535 0.00337114 0.00296686"/>
          <joint name="right_hip_roll_joint" pos="0 0 0" axis="1 0 0" range="-2.3563 0.7854" actuatorfrcrange="-150 150"/>
          <geom type="mesh" contype="0" conaffinity="0" group="1" density="0" rgba="0.752941 0.752941 0.752941 1" mesh="right_hip_roll_link"/>
          <geom size="0.07 0.025" pos="0 0 -0.09" type="cylinder" rgba="0.752941 0.752941 0.752941 1"/>
          <body name="right_hip_yaw_link" pos="0 0 -0.13">
            <inertial pos="-0.0107 0.008795 -0.120268" quat="0.697472 0.0822562 0.00814217 0.711829" mass="2.325" diaginertia="0.00969146 0.00888604 0.00293651"/>
            <joint name="right_hip_yaw_joint" pos="0 0 0" axis="0 0 1" range="-2.0944 2.0944" actuatorfrcrange="-90 90"/>
            <geom type="mesh" contype="0" conaffinity="0" group="1" density="0" rgba="0.752941 0.752941 0.752941 1" mesh="right_hip_yaw_link"/>
            <geom type="mesh" rgba="0.752941 0.752941 0.752941 1" mesh="right_hip_yaw_link"/>
            <body name="right_knee_link" pos="-0.015 0 -0.151">
              <inertial pos="0.004163 -0.000262 -0.138565" quat="0.99994 0.00282969 -0.0106115 -1.22531e-05" mass="1.83395" diaginertia="0.0104298 0.00990025 0.00194592"/>
              <joint name="right_knee_joint" pos="0 0 0" axis="0 1 0" range="-0.0873 2.0944" actuatorfrcrange="-150 150"/>
              <geom type="mesh" contype="0" conaffinity="0" group="1" density="0" rgba="0.752941 0.752941 0.752941 1" mesh="right_knee_link"/>
              <geom size="0.04 0.115" pos="0.01 0 -0.2" type="cylinder" rgba="0.752941 0.752941 0.752941 1"/>
              <body name="right_ankle_pitch_link" pos="0.015 -0.0005 -0.339">
                <inertial pos="-0.002351 0.000479 -0.006916" quat="0.344336 0.344336 -0.617602 0.617602" mass="0.102" diaginertia="2.22361e-05 1.77639e-05 1.7e-05"/>
                <joint name="right_ankle_pitch_joint" pos="0 0 0" axis="0 1 0" range="-0.9599 0.5218" actuatorfrcrange="-54 54"/>
                <geom type="mesh" contype="0" conaffinity="0" group="1" density="0" rgba="0.752941 0.752941 0.752941 1" mesh="right_ankle_pitch_link"/>
                <body name="right_ankle_roll_link" pos="0 0 -0.015">
                  <inertial pos="0.044949 3.2e-05 -0.035309" quat="-0.00358632 0.734652 -0.00406875 0.678422" mass="0.968" diaginertia="0.00496359 0.00487899 0.000595419"/>
                  <joint name="right_ankle_roll_joint" pos="0 0 0" axis="1 0 0" range="-0.1745 0.1745" actuatorfrcrange="-54 54"/>
                  <geom type="mesh" contype="0" conaffinity="0" group="1" density="0" rgba="0.752941 0.752941 0.752941 1" mesh="right_ankle_roll_link"/>
                  <geom size="0.005" pos="-0.06 0.035 -0.06" rgba="0.752941 0.752941 0.752941 1"/>
                  <geom size="0.005" pos="-0.06 -0.035 -0.06" rgba="0.752941 0.752941 0.752941 1"/>
                  <geom size="0.005" pos="0.13 0.035 -0.06" rgba="0.752941 0.752941 0.752941 1"/>
                  <geom size="0.005" pos="0.13 -0.035 -0.06" rgba="0.752941 0.752941 0.752941 1"/>
                  <geom size="0.005" pos="0.17 0.018 -0.058" rgba="0.752941 0.752941 0.752941 1"/>
                  <geom size="0.005" pos="0.17 -0.018 -0.058" rgba="0.752941 0.752941 0.752941 1"/>
                  <geom size="0.005" pos="-0.035 0.035 -0.06" rgba="0.752941 0.752941 0.752941 1"/>
                  <geom size="0.005" pos="-0.035 -0.035 -0.06" rgba="0.752941 0.752941 0.752941 1"/>
                  <geom size="0.005" pos="0.06 0.035 -0.06" rgba="0.752941 0.752941 0.752941 1"/>
                  <geom size="0.005" pos="0.06 -0.035 -0.06" rgba="0.752941 0.752941 0.752941 1"/>
                </body>
              </body>
            </body>
          </body>
        </body>
      </body>
      <body name="waist_yaw_link">
        <inertial pos="-0.025004 1e-06 0.041503" quat="0 0.73528 0 0.677763" mass="0.287" diaginertia="0.000603691 0.000469 0.000196309"/>
        <joint name="waist_yaw_joint" pos="0 0 0" axis="0 0 1" range="-1.5708 1.5708" actuatorfrcrange="-90 90"/>
        <geom type="mesh" contype="0" conaffinity="0" group="1" density="0" rgba="0.752941 0.752941 0.752941 1" mesh="waist_yaw_link"/>
        <geom size="0.04 0.04 0.005" pos="0 0 0.04" type="box" rgba="0.752941 0.752941 0.752941 1"/>
        <body name="waist_roll_link" pos="0 0 0.0615">
          <inertial pos="0 0 -1.7e-05" quat="0 0.707107 0 0.707107" mass="0.185" diaginertia="7.5e-05 5.5e-05 2.6e-05"/>
          <joint name="waist_roll_joint" pos="0 0 0" axis="1 0 0" range="-0.1745 0.1745" actuatorfrcrange="-90 90"/>
          <geom type="mesh" contype="0" conaffinity="0" group="1" density="0" rgba="0.752941 0.752941 0.752941 1" mesh="waist_roll_link"/>
          <geom type="mesh" rgba="0.752941 0.752941 0.752941 1" mesh="waist_roll_link"/>
          <body name="torso_link">
            <inertial pos="-0.00480175 0.000110024 0.265108" quat="0.999841 0.000167294 0.0178016 -0.000683073" mass="12.4908" diaginertia="0.314143 0.272447 0.0764862"/>
            <joint name="waist_pitch_joint" pos="0 0 0" axis="0 1 0" range="-0.3491 0.6981" actuatorfrcrange="-90 90"/>
            <geom type="mesh" contype="0" conaffinity="0" group="1" density="0" rgba="0.752941 0.752941 0.752941 1" mesh="waist_pitch_link"/>
            <geom type="mesh" rgba="0.752941 0.752941 0.752941 1" mesh="waist_pitch_link"/>
            <geom pos="0 0 0.4375" type="mesh" contype="0" conaffinity="0" group="1" density="0" rgba="0.752941 0.752941 0.752941 1" mesh="head_yaw_link"/>
            <geom pos="0 0 0.4375" type="mesh" rgba="0.752941 0.752941 0.752941 1" mesh="head_yaw_link"/>
            <geom pos="0 0 0.5795" type="mesh" contype="0" conaffinity="0" group="1" density="0" rgba="0.752941 0.752941 0.752941 1" mesh="head_pitch_link"/>
            <geom pos="0 0 0.5795" type="mesh" rgba="0.752941 0.752941 0.752941 1" mesh="head_pitch_link"/>
            <body name="left_shoulder_pitch_link" pos="0 0.1446 0.3935">
              <inertial pos="0.005662 0.045222 -4e-06" quat="0.601501 0.371748 -0.601501 0.371748" mass="0.82" diaginertia="0.000604 0.000578 0.000573"/>
              <joint name="left_shoulder_pitch_joint" pos="0 0 0" axis="0 1 0" range="-2.618 2.618" actuatorfrcrange="-80 80"/>
              <geom type="mesh" contype="0" conaffinity="0" group="1" density="0" rgba="0.752941 0.752941 0.752941 1" mesh="left_shoulder_pitch_link"/>
              <geom type="mesh" rgba="0.752941 0.752941 0.752941 1" mesh="left_shoulder_pitch_link"/>
              <body name="left_shoulder_roll_link" pos="0 0.047 0">
                <inertial pos="0.004162 6e-05 -0.097299" quat="0.688168 0.162556 0.162556 0.688168" mass="0.888" diaginertia="0.001422 0.0014176 0.0007054"/>
                <joint name="left_shoulder_roll_joint" pos="0 0 0" axis="1 0 0" range="-0.0873 3.2289" actuatorfrcrange="-80 80"/>
                <geom type="mesh" contype="0" conaffinity="0" group="1" density="0" rgba="0.752941 0.752941 0.752941 1" mesh="left_shoulder_roll_link"/>
                <geom type="mesh" rgba="0.752941 0.752941 0.752941 1" mesh="left_shoulder_roll_link"/>
                <body name="left_shoulder_yaw_link" pos="-0.00072034 0 -0.1346">
                  <inertial pos="0.006267 0.007667 -0.091718" quat="0.696333 0.00192978 -0.0814017 0.713085" mass="0.98" diaginertia="0.00140405 0.00136938 0.000763573"/>
                  <joint name="left_shoulder_yaw_joint" pos="0 0 0" axis="0 0 1" range="-2.618 2.618" actuatorfrcrange="-80 80"/>
                  <geom type="mesh" contype="0" conaffinity="0" group="1" density="0" rgba="0.752941 0.752941 0.752941 1" mesh="left_shoulder_yaw_link"/>
                  <geom type="mesh" rgba="0.752941 0.752941 0.752941 1" mesh="left_shoulder_yaw_link"/>
                  <body name="left_elbow_link" pos="0.0075 0 -0.1019">
                    <inertial pos="0.081388 0.010684 -0.008487" quat="0.204129 0.704737 -0.163861 0.659413" mass="0.516" diaginertia="0.000713308 0.00066173 0.000240962"/>
                    <joint name="left_elbow_joint" pos="0 0 0" axis="0 1 0" range="-0.6981 3.3161" actuatorfrcrange="-80 80"/>
                    <geom type="mesh" contype="0" conaffinity="0" group="1" density="0" rgba="0.752941 0.752941 0.752941 1" mesh="left_elbow_link"/>
                    <geom type="mesh" rgba="0.752941 0.752941 0.752941 1" mesh="left_elbow_link"/>
                    <body name="left_wrist_roll_link" pos="0.1 0.0019 -0.009">
                      <inertial pos="0.08529 -4.2e-05 -0.005123" quat="0.460214 0.536845 0.536845 0.460214" mass="0.67" diaginertia="0.00113 0.00105584 0.000420156"/>
                      <joint name="left_wrist_roll_joint" pos="0 0 0" axis="1 0 0" range="-2.618 2.618" actuatorfrcrange="-11.5 11.5"/>
                      <geom type="mesh" contype="0" conaffinity="0" group="1" density="0" rgba="0.752941 0.752941 0.752941 1" mesh="left_wrist_roll_link"/>
                      <geom type="mesh" rgba="0.752941 0.752941 0.752941 1" mesh="left_wrist_roll_link"/>
                      <body name="left_wrist_yaw_link" pos="0.1135 0 0">
                        <inertial pos="0.051473 0.006559 -0.001913" quat="0.598709 0.294471 0.367661 0.647811" mass="0.365" diaginertia="0.0001769 0.000172925 0.000118175"/>
                        <joint name="left_wrist_yaw_joint" pos="0 0 0" axis="0 0 1" range="-1.6581 1.5708" actuatorfrcrange="-11.5 11.5"/>
                        <geom type="mesh" contype="0" conaffinity="0" group="1" density="0" rgba="0.752941 0.752941 0.752941 1" mesh="left_wrist_yaw_link"/>
                        <geom type="mesh" rgba="0.752941 0.752941 0.752941 1" mesh="left_wrist_yaw_link"/>
                        <body name="left_wrist_pitch_link" pos="0.054 0 0">
                          <inertial pos="0.112572 -0.00616709 0.0100642" quat="0.689134 0.340149 0.55866 0.311917" mass="0.549" diaginertia="0.0019349 0.00153131 0.000570391"/>
                          <joint name="left_wrist_pitch_joint" pos="0 0 0" axis="0 1 0" range="-1.6581 1.4835" actuatorfrcrange="-11.5 11.5"/>
                          <geom type="mesh" contype="0" conaffinity="0" group="1" density="0" rgba="0.898039 0.917647 0.929412 1" mesh="left_wrist_pitch_link"/>
                          <geom type="mesh" rgba="0.898039 0.917647 0.929412 1" mesh="left_wrist_pitch_link"/>
                          <geom pos="0.052 0 0.001" quat="1 0 0 0" type="mesh" contype="0" conaffinity="0" group="1" density="0" rgba="1 1 1 1" mesh="left_hand_link"/>
                          <geom pos="0.052 0 0.001" quat="1 0 0 0" type="mesh" rgba="1 1 1 1" mesh="left_hand_link"/>
                        </body>
                      </body>
                    </body>
                  </body>
                </body>
              </body>
            </body>
            <body name="right_shoulder_pitch_link" pos="0 -0.1446 0.3935">
              <inertial pos="0.005662 -0.045222 -4e-06" quat="0.371748 0.601501 -0.371748 0.601501" mass="0.82" diaginertia="0.000604 0.000578 0.000573"/>
              <joint name="right_shoulder_pitch_joint" pos="0 0 0" axis="0 1 0" range="-2.618 2.618" actuatorfrcrange="-80 80"/>
              <geom type="mesh" contype="0" conaffinity="0" group="1" density="0" rgba="0.752941 0.752941 0.752941 1" mesh="right_shoulder_pitch_link"/>
              <geom type="mesh" rgba="0.752941 0.752941 0.752941 1" mesh="right_shoulder_pitch_link"/>
              <body name="right_shoulder_roll_link" pos="0 -0.047 0">
                <inertial pos="0.004162 -6e-05 -0.097299" quat="0.688168 0.162556 0.162556 0.688168" mass="0.888" diaginertia="0.001422 0.0014176 0.0007054"/>
                <joint name="right_shoulder_roll_joint" pos="0 0 0" axis="1 0 0" range="-3.2289 0.0873" actuatorfrcrange="-80 80"/>
                <geom type="mesh" contype="0" conaffinity="0" group="1" density="0" rgba="0.752941 0.752941 0.752941 1" mesh="right_shoulder_roll_link"/>
                <geom type="mesh" rgba="0.752941 0.752941 0.752941 1" mesh="right_shoulder_roll_link"/>
                <body name="right_shoulder_yaw_link" pos="-0.00072034 0 -0.1346">
                  <inertial pos="0.006267 -0.007667 -0.091718" quat="0.713085 -0.0814017 0.00192978 0.696333" mass="0.98" diaginertia="0.00140405 0.00136938 0.000763573"/>
                  <joint name="right_shoulder_yaw_joint" pos="0 0 0" axis="0 0 1" range="-2.618 2.618" actuatorfrcrange="-80 80"/>
                  <geom type="mesh" contype="0" conaffinity="0" group="1" density="0" rgba="0.752941 0.752941 0.752941 1" mesh="right_shoulder_yaw_link"/>
                  <geom type="mesh" rgba="0.752941 0.752941 0.752941 1" mesh="right_shoulder_yaw_link"/>
                  <body name="right_elbow_link" pos="0.0075 0 -0.1019">
                    <inertial pos="0.081388 -0.010683 -0.008487" quat="-0.204129 0.704737 0.163861 0.659413" mass="0.516" diaginertia="0.000713308 0.00066173 0.000240962"/>
                    <joint name="right_elbow_joint" pos="0 0 0" axis="0 1 0" range="-0.6981 3.3161" actuatorfrcrange="-80 80"/>
                    <geom type="mesh" contype="0" conaffinity="0" group="1" density="0" rgba="0.752941 0.752941 0.752941 1" mesh="right_elbow_link"/>
                    <geom type="mesh" rgba="0.752941 0.752941 0.752941 1" mesh="right_elbow_link"/>
                    <body name="right_wrist_roll_link" pos="0.1 -0.0019 -0.009">
                      <inertial pos="0.08529 4.2e-05 -0.005123" quat="0.460214 0.536845 0.536845 0.460214" mass="0.67" diaginertia="0.00113 0.00105584 0.000420156"/>
                      <joint name="right_wrist_roll_joint" pos="0 0 0" axis="1 0 0" range="-2.618 2.618" actuatorfrcrange="-11.5 11.5"/>
                      <geom type="mesh" contype="0" conaffinity="0" group="1" density="0" rgba="0.752941 0.752941 0.752941 1" mesh="right_wrist_roll_link"/>
                      <geom type="mesh" rgba="0.752941 0.752941 0.752941 1" mesh="right_wrist_roll_link"/>
                      <body name="right_wrist_yaw_link" pos="0.1135 0 0">
                        <inertial pos="0.051473 -0.006559 -0.001913" quat="0.647811 0.367661 0.294471 0.598709" mass="0.365" diaginertia="0.0001769 0.000172925 0.000118175"/>
                        <joint name="right_wrist_yaw_joint" pos="0 0 0" axis="0 0 1" range="-1.5708 1.6581" actuatorfrcrange="-11.5 11.5"/>
                        <geom type="mesh" contype="0" conaffinity="0" group="1" density="0" rgba="0.752941 0.752941 0.752941 1" mesh="right_wrist_yaw_link"/>
                        <geom type="mesh" rgba="0.752941 0.752941 0.752941 1" mesh="right_wrist_yaw_link"/>
                        <body name="right_wrist_pitch_link" pos="0.054 0 0">
                          <inertial pos="0.112572 0.00707784 0.00915344" quat="0.309661 0.559561 0.341853 0.688577" mass="0.549" diaginertia="0.00193583 0.00153132 0.000571665"/>
                          <joint name="right_wrist_pitch_joint" pos="0 0 0" axis="0 1 0" range="-1.6581 1.4835" actuatorfrcrange="-11.5 11.5"/>
                          <geom type="mesh" contype="0" conaffinity="0" group="1" density="0" rgba="1 1 1 1" mesh="right_wrist_pitch_link"/>
                          <geom type="mesh" rgba="1 1 1 1" mesh="right_wrist_pitch_link"/>
                          <geom pos="0.052 0.001 0" quat="1 0 0 0" type="mesh" contype="0" conaffinity="0" group="1" density="0" rgba="1 1 1 1" mesh="right_hand_link"/>
                          <geom pos="0.052 0.001 0" quat="1 0 0 0" type="mesh" rgba="1 1 1 1" mesh="right_hand_link"/>
                        </body>
                      </body>
                    </body>
                  </body>
                </body>
              </body>
            </body>
          </body>
        </body>
      </body>
    </body>
  </worldbody>
  <actuator>
    <motor name="left_hip_pitch_joint" joint="left_hip_pitch_joint"/>
    <motor name="left_hip_roll_joint" joint="left_hip_roll_joint"/>
    <motor name="left_hip_yaw_joint" joint="left_hip_yaw_joint"/>
    <motor name="left_knee_joint" joint="left_knee_joint"/>
    <motor name="left_ankle_pitch_joint" joint="left_ankle_pitch_joint"/>
    <motor name="left_ankle_roll_joint" joint="left_ankle_roll_joint"/>
    <motor name="right_hip_pitch_joint" joint="right_hip_pitch_joint"/>
    <motor name="right_hip_roll_joint" joint="right_hip_roll_joint"/>
    <motor name="right_hip_yaw_joint" joint="right_hip_yaw_joint"/>
    <motor name="right_knee_joint" joint="right_knee_joint"/>
    <motor name="right_ankle_pitch_joint" joint="right_ankle_pitch_joint"/>
    <motor name="right_ankle_roll_joint" joint="right_ankle_roll_joint"/>
    <motor name="waist_yaw_joint" joint="waist_yaw_joint"/>
    <motor name="waist_roll_joint" joint="waist_roll_joint"/>
    <motor name="waist_pitch_joint" joint="waist_pitch_joint"/>
    <motor name="left_shoulder_pitch_joint" joint="left_shoulder_pitch_joint"/>
    <motor name="left_shoulder_roll_joint" joint="left_shoulder_roll_joint"/>
    <motor name="left_shoulder_yaw_joint" joint="left_shoulder_yaw_joint"/>
    <motor name="left_elbow_joint" joint="left_elbow_joint"/>
    <motor name="left_wrist_roll_joint" joint="left_wrist_roll_joint"/>
    <motor name="left_wrist_yaw_joint" joint="left_wrist_yaw_joint"/>
    <motor name="left_wrist_pitch_joint" joint="left_wrist_pitch_joint"/> 
    <motor name="right_shoulder_pitch_joint" joint="right_shoulder_pitch_joint"/>
    <motor name="right_shoulder_roll_joint" joint="right_shoulder_roll_joint"/>
    <motor name="right_shoulder_yaw_joint" joint="right_shoulder_yaw_joint"/>
    <motor name="right_elbow_joint" joint="right_elbow_joint"/>
    <motor name="right_wrist_roll_joint" joint="right_wrist_roll_joint"/>
    <motor name="right_wrist_yaw_joint" joint="right_wrist_yaw_joint"/>
    <motor name="right_wrist_pitch_joint" joint="right_wrist_pitch_joint"/>
  </actuator>

  <sensor>
    <framequat name="orientation" objtype="site" objname="imu_in_pelvis" noise="0"/>
    <gyro name="imu-pelvis-angular-velocity" site="imu_in_pelvis" noise="0.001"/>
    <framepos name="body-linear-pos" objtype="site" objname="imu_in_pelvis"/>
    <velocimeter name="body-linear-vel" site="imu_in_pelvis"/>
    <accelerometer name="body-linear-acceleration" site="imu_in_pelvis" noise="0.001"/>

  </sensor>
  <statistic center="1.0 0.7 1.0" extent="0.8"/>
  <visual>
    <headlight diffuse="0.6 0.6 0.6" ambient="0.1 0.1 0.1" specular="0.9 0.9 0.9"/>
    <rgba haze="0.15 0.25 0.35 1"/>
    <global azimuth="-140" elevation="-20"/>
  </visual>
  <asset>
    <texture type="skybox" builtin="flat" rgb1="0 0 0" rgb2="0 0 0" width="512" height="3072"/>
    <texture type="2d" name="groundplane" builtin="checker" mark="edge" rgb1="0.2 0.3 0.4" rgb2="0.1 0.2 0.3" markrgb="0.8 0.8 0.8" width="300" height="300"/>
    <material name="groundplane" texture="groundplane" texuniform="true" texrepeat="5 5" reflectance="0.2"/>
  </asset>
  <worldbody>
    <light pos="1 0 3.5" dir="0 0 -1" directional="true"/>
    <geom name="floor" size="0 0 0.05" type="plane" material="groundplane"/>
  </worldbody>
  <keyframe>
  <key name="home"
    qpos="
    0 0 0.87
    1 0 0 0
    -0.1 0.0 -0.07 0.25 -0.14 0.0
    -0.1 0.0 0.07 0.25 -0.14 0.0
    0.0 0.0 0.0
    0.1 0.15 -0.1 1.25 0.0 0.0 0.0
    0.1 -0.15 0.1 1.25 0.0 0.0 0.0
    "/>
  </keyframe>
</mujoco>
