<?xml version="1.0" encoding="utf-8"?>
<!-- This URDF was automatically created by SolidWorks to URDF Exporter! Originally created by Stephen Brawner (brawner@gmail.com) 
     Commit Version: 1.6.0-4-g7f85cfe  Build Version: 1.6.7995.38578
     For more information, please see http://wiki.ros.org/sw_urdf_exporter -->
<robot
  name="v1.1_Whole_u1.1_1216">
  <link
    name="base_link">
    <inertial>
      <origin
        xyz="-0.00011 0 -0.04947"
        rpy="0 0 0" />
      <mass
        value="5.6115" />
      <inertia
        ixx="0.02782"
        ixy="0"
        ixz="1E-05"
        iyy="0.01883"
        iyz="0"
        izz="0.0298" />
    </inertial>
    <visual>
      <origin
        xyz="0 0 0"
        rpy="0 0 0" />
      <geometry>
        <mesh
          filename="package://whole_v1.1_u1.0_1125/meshes/base_link.STL" />
      </geometry>
      <material
        name="">
        <color
          rgba="0.75294 0.75294 0.75294 1" />
      </material>
    </visual>
    <collision>
      <origin
        xyz="0 0 0"
        rpy="0 0 0" />
      <geometry>
        <mesh
          filename="package://whole_v1.1_u1.0_1125/meshes/base_link.STL" />
      </geometry>
    </collision>
  </link>
  <link
    name="left_hip_pitch_link">
    <inertial>
      <origin
        xyz="0.0037 0.02157 -0.02824"
        rpy="0 0 0" />
      <mass
        value="2.2386" />
      <inertia
        ixx="0.00513"
        ixy="0.00017"
        ixz="-2E-05"
        iyy="0.00405"
        iyz="-0.00025"
        izz="0.00427" />
    </inertial>
    <visual>
      <origin
        xyz="0 0 0"
        rpy="0 0 0" />
      <geometry>
        <mesh
          filename="package://whole_v1.1_u1.0_1125/meshes/left_hip_pitch_link.STL" />
      </geometry>
      <material
        name="">
        <color
          rgba="0.75294 0.75294 0.75294 1" />
      </material>
    </visual>
    <collision>
      <origin
        xyz="0 0 0"
        rpy="0 0 0" />
      <geometry>
        <mesh
          filename="package://whole_v1.1_u1.0_1125/meshes/left_hip_pitch_link.STL" />
      </geometry>
    </collision>
  </link>
  <joint
    name="left_hip_pitch_joint"
    type="revolute">
    <origin
      xyz="0 0.11619 -0.12455"
      rpy="-0.7854 0 0" />
    <parent
      link="base_link" />
    <child
      link="left_hip_pitch_link" />
    <axis
      xyz="0 1 0" />
    <limit
      lower="-0.9643"
      upper="1.2610"
      effort="127.5"
      velocity="13.4041" />
  </joint>
  <link
    name="left_hip_roll_link">
    <inertial>
      <origin
        xyz="0.0015 3E-05 -0.08423"
        rpy="0 0 0" />
      <mass
        value="1.4586" />
      <inertia
        ixx="0.00306"
        ixy="0"
        ixz="0.00019"
        iyy="0.00447"
        iyz="0"
        izz="0.00319" />
    </inertial>
    <visual>
      <origin
        xyz="0 0 0"
        rpy="0 0 0" />
      <geometry>
        <mesh
          filename="package://whole_v1.1_u1.0_1125/meshes/left_hip_roll_link.STL" />
      </geometry>
      <material
        name="">
        <color
          rgba="0.75294 0.75294 0.75294 1" />
      </material>
    </visual>
    <collision>
      <origin
        xyz="0 0 0"
        rpy="0 0 0" />
      <geometry>
        <mesh
          filename="package://whole_v1.1_u1.0_1125/meshes/left_hip_roll_link.STL" />
      </geometry>
    </collision>
  </link>
  <joint
    name="left_hip_roll_joint"
    type="revolute">
    <origin
      xyz="-0.001 0.03 -0.03"
      rpy="0.7854 0 0" />
    <parent
      link="left_hip_pitch_link" />
    <child
      link="left_hip_roll_link" />
    <axis
      xyz="1 0 0" />
    <limit
      lower="-0.6676"
      upper="0.6676"
      effort="127.5"
      velocity="13.4041" />
  </joint>
  <link
    name="left_hip_yaw_link">
    <inertial>
      <origin
        xyz="-0.01065 -0.00925 -0.12007"
        rpy="0 0 0" />
      <mass
        value="2.292" />
      <inertia
        ixx="0.00868"
        ixy="7E-05"
        ixz="0.00075"
        iyy="0.00955"
        iyz="0.00072"
        izz="0.00304" />
    </inertial>
    <visual>
      <origin
        xyz="0 0 0"
        rpy="0 0 0" />
      <geometry>
        <mesh
          filename="package://whole_v1.1_u1.0_1125/meshes/left_hip_yaw_link.STL" />
      </geometry>
      <material
        name="">
        <color
          rgba="0.75294 0.75294 0.75294 1" />
      </material>
    </visual>
    <collision>
      <origin
        xyz="0 0 0"
        rpy="0 0 0" />
      <geometry>
        <mesh
          filename="package://whole_v1.1_u1.0_1125/meshes/left_hip_yaw_link.STL" />
      </geometry>
    </collision>
  </link>
  <joint
    name="left_hip_yaw_joint"
    type="revolute">
    <origin
      xyz="0 0 -0.13"
      rpy="0 0 0" />
    <parent
      link="left_hip_roll_link" />
    <child
      link="left_hip_yaw_link" />
    <axis
      xyz="0 0 1" />
    <limit
      lower="-1.7802"
      upper="1.7802"
      effort="76.5"
      velocity="16.1268" />
  </joint>
  <link
    name="left_knee_link">
    <inertial>
      <origin
        xyz="0.00377 -0.00224 -0.13833"
        rpy="0 0 0" />
      <mass
        value="1.7311" />
      <inertia
        ixx="0.0099"
        ixy="0"
        ixz="-0.00015"
        iyy="0.00937"
        iyz="3E-05"
        izz="0.00182" />
    </inertial>
    <visual>
      <origin
        xyz="0 0 0"
        rpy="0 0 0" />
      <geometry>
        <mesh
          filename="package://whole_v1.1_u1.0_1125/meshes/left_knee_link.STL" />
      </geometry>
      <material
        name="">
        <color
          rgba="0.75294 0.75294 0.75294 1" />
      </material>
    </visual>
    <collision>
      <origin
        xyz="0 0 0"
        rpy="0 0 0" />
      <geometry>
        <mesh
          filename="package://whole_v1.1_u1.0_1125/meshes/left_knee_link.STL" />
      </geometry>
    </collision>
  </link>
  <joint
    name="left_knee_joint"
    type="revolute">
    <origin
      xyz="-0.015 0 -0.151"
      rpy="0 0 0" />
    <parent
      link="left_hip_yaw_link" />
    <child
      link="left_knee_link" />
    <axis
      xyz="0 1 0" />
    <limit
      lower="0"
      upper="1.7802"
      effort="127.5"
      velocity="13.4041" />
  </joint>
  <link
    name="left_ankle_pitch_link">
    <inertial>
      <origin
        xyz="-0.0023511 -0.0004785 -0.0069164"
        rpy="0 0 0" />
      <mass
        value="0.081064" />
      <inertia
        ixx="2E-05"
        ixy="0"
        ixz="0"
        iyy="1E-05"
        iyz="0"
        izz="2E-05" />
    </inertial>
    <visual>
      <origin
        xyz="0 0 0"
        rpy="0 0 0" />
      <geometry>
        <mesh
          filename="package://whole_v1.1_u1.0_1125/meshes/left_ankle_pitch_link.STL" />
      </geometry>
      <material
        name="">
        <color
          rgba="0.75294 0.75294 0.75294 1" />
      </material>
    </visual>
    <collision>
      <origin
        xyz="0 0 0"
        rpy="0 0 0" />
      <geometry>
        <mesh
          filename="package://whole_v1.1_u1.0_1125/meshes/left_ankle_pitch_link.STL" />
      </geometry>
    </collision>
  </link>
  <joint
    name="left_ankle_pitch_link"
    type="revolute">
    <origin
      xyz="0.015 -0.002 -0.339"
      rpy="0 0 0" />
    <parent
      link="left_knee_link" />
    <child
      link="left_ankle_pitch_link" />
    <axis
      xyz="0 1 0" />
    <limit
      lower="-0.7269"
      upper="0.2225"
      effort="45.9"
      velocity="8.0634" />
  </joint>
  <link
    name="left_ankle_roll_link">
    <inertial>
      <origin
        xyz="0.04469 -3.2121E-05 -0.035309"
        rpy="0 0 0" />
      <mass
        value="0.83613" />
      <inertia
        ixx="0.00054"
        ixy="0"
        ixz="-0.0003"
        iyy="0.00421"
        iyz="0"
        izz="0.00426" />
    </inertial>
    <visual>
      <origin
        xyz="0 0 0"
        rpy="0 0 0" />
      <geometry>
        <mesh
          filename="package://whole_v1.1_u1.0_1125/meshes/left_ankle_roll_link.STL" />
      </geometry>
      <material
        name="">
        <color
          rgba="0.75294 0.75294 0.75294 1" />
      </material>
    </visual>
    <collision>
      <origin
        xyz="0 0 0"
        rpy="0 0 0" />
      <geometry>
        <mesh
          filename="package://whole_v1.1_u1.0_1125/meshes/left_ankle_roll_link.STL" />
      </geometry>
    </collision>
  </link>
  <joint
    name="left_ankle_roll_joint"
    type="revolute">
    <origin
      xyz="0 0 -0.015"
      rpy="0 0 0" />
    <parent
      link="left_ankle_pitch_link" />
    <child
      link="left_ankle_roll_link" />
    <axis
      xyz="1 0 0" />
    <limit
      lower="-0.1484"
      upper="0.1484"
      effort="45.9"
      velocity="8.0634" />
  </joint>
  <link
    name="right_hip_pitch_link">
    <inertial>
      <origin
        xyz="0.00753 -0.02164 -0.02818"
        rpy="0 0 0" />
      <mass
        value="2.2312" />
      <inertia
        ixx="0.00511"
        ixy="-0.00025"
        ixz="-4E-05"
        iyy="0.00419"
        iyz="0.00024"
        izz="0.00443" />
    </inertial>
    <visual>
      <origin
        xyz="0 0 0"
        rpy="0 0 0" />
      <geometry>
        <mesh
          filename="package://whole_v1.1_u1.0_1125/meshes/right_hip_pitch_link.STL" />
      </geometry>
      <material
        name="">
        <color
          rgba="0.75294 0.75294 0.75294 1" />
      </material>
    </visual>
    <collision>
      <origin
        xyz="0 0 0"
        rpy="0 0 0" />
      <geometry>
        <mesh
          filename="package://whole_v1.1_u1.0_1125/meshes/right_hip_pitch_link.STL" />
      </geometry>
    </collision>
  </link>
  <joint
    name="right_hip_pitch_joint"
    type="revolute">
    <origin
      xyz="0 -0.11619 -0.12455"
      rpy="0.7854 0 0" />
    <parent
      link="base_link" />
    <child
      link="right_hip_pitch_link" />
    <axis
      xyz="0 1 0" />
    <limit
      lower="-0.9643"
      upper="1.2610"
      effort="127.5"
      velocity="13.4041" />
  </joint>
  <link
    name="right_hip_roll_link">
    <inertial>
      <origin
        xyz="0.00151 0 -0.08423"
        rpy="0 0 0" />
      <mass
        value="1.4586" />
      <inertia
        ixx="0.00304"
        ixy="1E-05"
        ixz="0.00019"
        iyy="0.00448"
        iyz="0"
        izz="0.00319" />
    </inertial>
    <visual>
      <origin
        xyz="0 0 0"
        rpy="0 0 0" />
      <geometry>
        <mesh
          filename="package://whole_v1.1_u1.0_1125/meshes/right_hip_roll_link.STL" />
      </geometry>
      <material
        name="">
        <color
          rgba="0.75294 0.75294 0.75294 1" />
      </material>
    </visual>
    <collision>
      <origin
        xyz="0 0 0"
        rpy="0 0 0" />
      <geometry>
        <mesh
          filename="package://whole_v1.1_u1.0_1125/meshes/right_hip_roll_link.STL" />
      </geometry>
    </collision>
  </link>
  <joint
    name="right_hip_roll_joint"
    type="revolute">
    <origin
      xyz="0.0055 -0.03 -0.03"
      rpy="-0.7854 0 0" />
    <parent
      link="right_hip_pitch_link" />
    <child
      link="right_hip_roll_link" />
    <axis
      xyz="1 0 0" />
    <limit
      lower="-0.6676"
      upper="0.6676"
      effort="127.5"
      velocity="13.4041" />
  </joint>
  <link
    name="right_hip_yaw_link">
    <inertial>
      <origin
        xyz="-0.01065 0.00923 -0.11999"
        rpy="0 0 0" />
      <mass
        value="2.2898" />
      <inertia
        ixx="0.00866"
        ixy="-7E-05"
        ixz="0.00075"
        iyy="0.00954"
        iyz="-0.00072"
        izz="0.00304" />
    </inertial>
    <visual>
      <origin
        xyz="0 0 0"
        rpy="0 0 0" />
      <geometry>
        <mesh
          filename="package://whole_v1.1_u1.0_1125/meshes/right_hip_yaw_link.STL" />
      </geometry>
      <material
        name="">
        <color
          rgba="0.75294 0.75294 0.75294 1" />
      </material>
    </visual>
    <collision>
      <origin
        xyz="0 0 0"
        rpy="0 0 0" />
      <geometry>
        <mesh
          filename="package://whole_v1.1_u1.0_1125/meshes/right_hip_yaw_link.STL" />
      </geometry>
    </collision>
  </link>
  <joint
    name="right_hip_yaw_joint"
    type="revolute">
    <origin
      xyz="0 0 -0.13"
      rpy="0 0 0" />
    <parent
      link="right_hip_roll_link" />
    <child
      link="right_hip_yaw_link" />
    <axis
      xyz="0 0 1" />
    <limit
      lower="-1.7802"
      upper="1.7802"
      effort="76.5"
      velocity="16.1268" />
  </joint>
  <link
    name="right_knee_link">
    <inertial>
      <origin
        xyz="0.00355 -0.00047 -0.13985"
        rpy="0 0 0" />
      <mass
        value="1.7443" />
      <inertia
        ixx="0.01043"
        ixy="0"
        ixz="-0.00018"
        iyy="0.00991"
        iyz="-3E-05"
        izz="0.00184" />
    </inertial>
    <visual>
      <origin
        xyz="0 0 0"
        rpy="0 0 0" />
      <geometry>
        <mesh
          filename="package://whole_v1.1_u1.0_1125/meshes/right_knee_link.STL" />
      </geometry>
      <material
        name="">
        <color
          rgba="0.75294 0.75294 0.75294 1" />
      </material>
    </visual>
    <collision>
      <origin
        xyz="0 0 0"
        rpy="0 0 0" />
      <geometry>
        <mesh
          filename="package://whole_v1.1_u1.0_1125/meshes/right_knee_link.STL" />
      </geometry>
    </collision>
  </link>
  <joint
    name="right_knee_joint"
    type="revolute">
    <origin
      xyz="-0.015 0 -0.151"
      rpy="0 0 0" />
    <parent
      link="right_hip_yaw_link" />
    <child
      link="right_knee_link" />
    <axis
      xyz="0 1 0" />
    <limit
      lower="0"
      upper="1.7802"
      effort="127.5"
      velocity="13.4041" />
  </joint>
  <link
    name="right_ankle_pitch_link">
    <inertial>
      <origin
        xyz="-0.00281 0.00057 -0.008265"
        rpy="0 0 0" />
      <mass
        value="0.06784" />
      <inertia
        ixx="1E-05"
        ixy="0"
        ixz="0"
        iyy="1E-05"
        iyz="0"
        izz="1E-05" />
    </inertial>
    <visual>
      <origin
        xyz="0 0 0"
        rpy="0 0 0" />
      <geometry>
        <mesh
          filename="package://whole_v1.1_u1.0_1125/meshes/right_ankle_pitch_link.STL" />
      </geometry>
      <material
        name="">
        <color
          rgba="0.75294 0.75294 0.75294 1" />
      </material>
    </visual>
    <collision>
      <origin
        xyz="0 0 0"
        rpy="0 0 0" />
      <geometry>
        <mesh
          filename="package://whole_v1.1_u1.0_1125/meshes/right_ankle_pitch_link.STL" />
      </geometry>
    </collision>
  </link>
  <joint
    name="right_ankle_pitch_joint"
    type="revolute">
    <origin
      xyz="0.015 -0.0007 -0.339"
      rpy="0 0 0" />
    <parent
      link="right_knee_link" />
    <child
      link="right_ankle_pitch_link" />
    <axis
      xyz="0 1 0" />
    <limit
      lower="-0.7269"
      upper="0.2225"
      effort="45.9"
      velocity="8.0634" />
  </joint>
  <link
    name="right_ankle_roll_link">
    <inertial>
      <origin
        xyz="0.044949 3.2367E-05 -0.03559"
        rpy="0 0 0" />
      <mass
        value="0.82952" />
      <inertia
        ixx="0.00053"
        ixy="0"
        ixz="-0.00029"
        iyy="0.0042"
        iyz="0"
        izz="0.00426" />
    </inertial>
    <visual>
      <origin
        xyz="0 0 0"
        rpy="0 0 0" />
      <geometry>
        <mesh
          filename="package://whole_v1.1_u1.0_1125/meshes/right_ankle_roll_link.STL" />
      </geometry>
      <material
        name="">
        <color
          rgba="0.75294 0.75294 0.75294 1" />
      </material>
    </visual>
    <collision>
      <origin
        xyz="0 0 0"
        rpy="0 0 0" />
      <geometry>
        <mesh
          filename="package://whole_v1.1_u1.0_1125/meshes/right_ankle_roll_link.STL" />
      </geometry>
    </collision>
  </link>
  <joint
    name="right_ankle_roll_joint"
    type="revolute">
    <origin
      xyz="0 0 -0.015"
      rpy="0 0 0" />
    <parent
      link="right_ankle_pitch_link" />
    <child
      link="right_ankle_roll_link" />
    <axis
      xyz="1 0 0" />
    <limit
      lower="-0.1484"
      upper="0.1484"
      effort="45.9"
      velocity="8.0634" />
  </joint>
  <link
    name="waist_yaw_link">
    <inertial>
      <origin
        xyz="-0.025004 1.113E-06 0.041503"
        rpy="0 0 0" />
      <mass
        value="0.22089" />
      <inertia
        ixx="0.00015"
        ixy="0"
        ixz="-3E-05"
        iyy="0.00036"
        iyz="0"
        izz="0.00046" />
    </inertial>
    <visual>
      <origin
        xyz="0 0 0"
        rpy="0 0 0" />
      <geometry>
        <mesh
          filename="package://whole_v1.1_u1.0_1125/meshes/waist_yaw_link.STL" />
      </geometry>
      <material
        name="">
        <color
          rgba="0.75294 0.75294 0.75294 1" />
      </material>
    </visual>
    <collision>
      <origin
        xyz="0 0 0"
        rpy="0 0 0" />
      <geometry>
        <mesh
          filename="package://whole_v1.1_u1.0_1125/meshes/waist_yaw_link.STL" />
      </geometry>
    </collision>
  </link>
  <joint
    name="waist_yaw_joint"
    type="revolute">
    <origin
      xyz="0 0 0"
      rpy="0 0 0" />
    <parent
      link="base_link" />
    <child
      link="waist_yaw_link" />
    <axis
      xyz="0 0 1" />
    <limit
      lower="-1.335"
      upper="1.335"
      effort="76.5"
      velocity="16.1268" />
  </joint>
  <link
    name="waist_roll_link">
    <inertial>
      <origin
        xyz="1.117E-08 2.7353E-09 -1.6907E-05"
        rpy="0 0 0" />
      <mass
        value="0.044984" />
      <inertia
        ixx="1E-05"
        ixy="0"
        ixz="0"
        iyy="1E-05"
        iyz="0"
        izz="2E-05" />
    </inertial>
    <visual>
      <origin
        xyz="0 0 0"
        rpy="0 0 0" />
      <geometry>
        <mesh
          filename="package://whole_v1.1_u1.0_1125/meshes/waist_roll_link.STL" />
      </geometry>
      <material
        name="">
        <color
          rgba="0.75294 0.75294 0.75294 1" />
      </material>
    </visual>
    <collision>
      <origin
        xyz="0 0 0"
        rpy="0 0 0" />
      <geometry>
        <mesh
          filename="package://whole_v1.1_u1.0_1125/meshes/waist_roll_link.STL" />
      </geometry>
    </collision>
  </link>
  <joint
    name="waist_roll_joint"
    type="revolute">
    <origin
      xyz="0 0 0.0615"
      rpy="0 0 0" />
    <parent
      link="waist_yaw_link" />
    <child
      link="waist_roll_link" />
    <axis
      xyz="1 0 0" />
    <limit
      lower="-0.1484"
      upper="0.1484"
      effort="51"
      velocity="13.1947" />
  </joint>
  <link
    name="waist_pitch_link">
    <inertial>
      <origin
        xyz="-0.00588 0.00011 0.23362"
        rpy="0 0 0" />
      <mass
        value="16.092" />
      <inertia
        ixx="0.24149"
        ixy="-3E-05"
        ixz="0.00442"
        iyy="0.19348"
        iyz="-0.00033"
        izz="0.09835" />
    </inertial>
    <visual>
      <origin
        xyz="0 0 0"
        rpy="0 0 0" />
      <geometry>
        <mesh
          filename="package://whole_v1.1_u1.0_1125/meshes/waist_pitch_link.STL" />
      </geometry>
      <material
        name="">
        <color
          rgba="0.75294 0.75294 0.75294 1" />
      </material>
    </visual>
    <collision>
      <origin
        xyz="0 0 0"
        rpy="0 0 0" />
      <geometry>
        <mesh
          filename="package://whole_v1.1_u1.0_1125/meshes/waist_pitch_link.STL" />
      </geometry>
    </collision>
  </link>
  <joint
    name="waist_pitch_joint"
    type="revolute">
    <origin
      xyz="0 0 0"
      rpy="0 0 0" />
    <parent
      link="waist_roll_link" />
    <child
      link="waist_pitch_link" />
    <axis
      xyz="0 1 0" />
    <limit
      lower="-0.2967"
      upper="0.5934"
      effort="51"
      velocity="13.1947" />
  </joint>
  <link
    name="head_yaw_link">
    <inertial>
      <origin
        xyz="-0.00147 -0.00171 0.1013"
        rpy="0 0 0" />
      <mass
        value="0.87994" />
      <inertia
        ixx="0.00202"
        ixy="2E-05"
        ixz="1E-05"
        iyy="0.00184"
        iyz="-2E-05"
        izz="0.00072" />
    </inertial>
    <visual>
      <origin
        xyz="0 0 0"
        rpy="0 0 0" />
      <geometry>
        <mesh
          filename="package://whole_v1.1_u1.0_1125/meshes/head_yaw_link.STL" />
      </geometry>
      <material
        name="">
        <color
          rgba="0.75294 0.75294 0.75294 1" />
      </material>
    </visual>
    <collision>
      <origin
        xyz="0 0 0"
        rpy="0 0 0" />
      <geometry>
        <mesh
          filename="package://whole_v1.1_u1.0_1125/meshes/head_yaw_link.STL" />
      </geometry>
    </collision>
  </link>
  <joint
    name="head_yaw_joint"
    type="revolute">
    <origin
      xyz="0 0 0.4375"
      rpy="0 0 0" />
    <parent
      link="waist_pitch_link" />
    <child
      link="head_yaw_link" />
    <axis
      xyz="0 0 1" />
    <limit
      lower="-1.335"
      upper="1.335"
      effort="11.9"
      velocity="27.2271" />
  </joint>
  <link
    name="head_pitch_link">
    <inertial>
      <origin
        xyz="0.02472 0.00516 0.05419"
        rpy="0 0 0" />
      <mass
        value="0.31183" />
      <inertia
        ixx="0.00047"
        ixy="-6E-05"
        ixz="-0.00022"
        iyy="0.00068"
        iyz="0"
        izz="0.0005" />
    </inertial>
    <visual>
      <origin
        xyz="0 0 0"
        rpy="0 0 0" />
      <geometry>
        <mesh
          filename="package://whole_v1.1_u1.0_1125/meshes/head_pitch_link.STL" />
      </geometry>
      <material
        name="">
        <color
          rgba="0.75294 0.75294 0.75294 1" />
      </material>
    </visual>
    <collision>
      <origin
        xyz="0 0 0"
        rpy="0 0 0" />
      <geometry>
        <mesh
          filename="package://whole_v1.1_u1.0_1125/meshes/head_pitch_link.STL" />
      </geometry>
    </collision>
  </link>
  <joint
    name="head_pitch_joint"
    type="revolute">
    <origin
      xyz="0 0 0.142"
      rpy="0 0 0" />
    <parent
      link="head_yaw_link" />
    <child
      link="head_pitch_link" />
    <axis
      xyz="0 1 0" />
    <limit
      lower="-0.5637"
      upper="0.2225"
      effort="11.9"
      velocity="27.2271" />
  </joint>
  <link
    name="left_shoulder_pitch_link">
    <inertial>
      <origin
        xyz="0.00566 0.04522 0"
        rpy="0 0 0" />
      <mass
        value="0.81088" />
      <inertia
        ixx="0.00057"
        ixy="0"
        ixz="0"
        iyy="0.00057"
        iyz="0"
        izz="0.0006" />
    </inertial>
    <visual>
      <origin
        xyz="0 0 0"
        rpy="0 0 0" />
      <geometry>
        <mesh
          filename="package://whole_v1.1_u1.0_1125/meshes/left_shoulder_pitch_link.STL" />
      </geometry>
      <material
        name="">
        <color
          rgba="0.75294 0.75294 0.75294 1" />
      </material>
    </visual>
    <collision>
      <origin
        xyz="0 0 0"
        rpy="0 0 0" />
      <geometry>
        <mesh
          filename="package://whole_v1.1_u1.0_1125/meshes/left_shoulder_pitch_link.STL" />
      </geometry>
    </collision>
  </link>
  <joint
    name="left_shoulder_pitch_joint"
    type="revolute">
    <origin
      xyz="0 0.1446 0.3935"
      rpy="0 0 0" />
    <parent
      link="waist_pitch_link" />
    <child
      link="left_shoulder_pitch_link" />
    <axis
      xyz="0 1 0" />
    <limit
      lower="-2.2253"
      upper="2.2253"
      effort="68"
      velocity="2.618" />
  </joint>
  <link
    name="left_shoulder_roll_link">
    <inertial>
      <origin
        xyz="0.00416 6E-05 -0.0973"
        rpy="0 0 0" />
      <mass
        value="0.88662" />
      <inertia
        ixx="0.00127"
        ixy="0"
        ixz="0.00028"
        iyy="0.00142"
        iyz="0"
        izz="0.00085" />
    </inertial>
    <visual>
      <origin
        xyz="0 0 0"
        rpy="0 0 0" />
      <geometry>
        <mesh
          filename="package://whole_v1.1_u1.0_1125/meshes/left_shoulder_roll_link.STL" />
      </geometry>
      <material
        name="">
        <color
          rgba="0.75294 0.75294 0.75294 1" />
      </material>
    </visual>
    <collision>
      <origin
        xyz="0 0 0"
        rpy="0 0 0" />
      <geometry>
        <mesh
          filename="package://whole_v1.1_u1.0_1125/meshes/left_shoulder_roll_link.STL" />
      </geometry>
    </collision>
  </link>
  <joint
    name="left_shoulder_roll_link"
    type="revolute">
    <origin
      xyz="0 0.047 0"
      rpy="0 0 0" />
    <parent
      link="left_shoulder_pitch_link" />
    <child
      link="left_shoulder_roll_link" />
    <axis
      xyz="1 0 0" />
    <limit
      lower="0"
      upper="2.5962"
      effort="68"
      velocity="2.618" />
  </joint>
  <link
    name="left_shoulder_yaw_link">
    <inertial>
      <origin
        xyz="0.00627 0.00767 -0.09172"
        rpy="0 0 0" />
      <mass
        value="0.99118" />
      <inertia
        ixx="0.00138"
        ixy="1E-05"
        ixz="-7E-05"
        iyy="0.00141"
        iyz="-8E-05"
        izz="0.00079" />
    </inertial>
    <visual>
      <origin
        xyz="0 0 0"
        rpy="0 0 0" />
      <geometry>
        <mesh
          filename="package://whole_v1.1_u1.0_1125/meshes/left_shoulder_yaw_link.STL" />
      </geometry>
      <material
        name="">
        <color
          rgba="0.75294 0.75294 0.75294 1" />
      </material>
    </visual>
    <collision>
      <origin
        xyz="0 0 0"
        rpy="0 0 0" />
      <geometry>
        <mesh
          filename="package://whole_v1.1_u1.0_1125/meshes/left_shoulder_yaw_link.STL" />
      </geometry>
    </collision>
  </link>
  <joint
    name="left_shoulder_yaw_joint"
    type="revolute">
    <origin
      xyz="-0.00072034 0 -0.1346"
      rpy="0 0 0" />
    <parent
      link="left_shoulder_roll_link" />
    <child
      link="left_shoulder_yaw_link" />
    <axis
      xyz="0 0 1" />
    <limit
      lower="-0.2225 "
      upper="0.2225 "
      effort="68"
      velocity="3.1416" />
  </joint>
  <link
    name="left_elbow_link">
    <inertial>
      <origin
        xyz="0.08139 0.01068 -0.00849"
        rpy="0 0 0" />
      <mass
        value="0.53702" />
      <inertia
        ixx="0.00036"
        ixy="-0.00019"
        ixz="-2E-05"
        iyy="0.00058"
        iyz="1E-05"
        izz="0.00074" />
    </inertial>
    <visual>
      <origin
        xyz="0 0 0"
        rpy="0 0 0" />
      <geometry>
        <mesh
          filename="package://whole_v1.1_u1.0_1125/meshes/left_elbow_link.STL" />
      </geometry>
      <material
        name="">
        <color
          rgba="0.75294 0.75294 0.75294 1" />
      </material>
    </visual>
    <collision>
      <origin
        xyz="0 0 0"
        rpy="0 0 0" />
      <geometry>
        <mesh
          filename="package://whole_v1.1_u1.0_1125/meshes/left_elbow_link.STL" />
      </geometry>
    </collision>
  </link>
  <joint
    name="left_elbow_joint"
    type="revolute">
    <origin
      xyz="0.0075 0 -0.1019"
      rpy="0 0 0" />
    <parent
      link="left_shoulder_yaw_link" />
    <child
      link="left_elbow_link" />
    <axis
      xyz="0 1 0" />
    <limit
      lower=" -0.5934"
      upper="2.8187"
      effort="68"
      velocity="3.1416" />
  </joint>
  <link
    name="left_wrist_roll_link">
    <inertial>
      <origin
        xyz="0.08529 0.00512 -4E-05"
        rpy="0 0 0" />
      <mass
        value="0.67942" />
      <inertia
        ixx="0.00044"
        ixy="0.0001"
        ixz="0"
        iyy="0.00106"
        iyz="0"
        izz="0.00115" />
    </inertial>
    <visual>
      <origin
        xyz="0 0 0"
        rpy="0 0 0" />
      <geometry>
        <mesh
          filename="package://whole_v1.1_u1.0_1125/meshes/left_wrist_roll_link.STL" />
      </geometry>
      <material
        name="">
        <color
          rgba="0.75294 0.75294 0.75294 1" />
      </material>
    </visual>
    <collision>
      <origin
        xyz="0 0 0"
        rpy="0 0 0" />
      <geometry>
        <mesh
          filename="package://whole_v1.1_u1.0_1125/meshes/left_wrist_roll_link.STL" />
      </geometry>
    </collision>
  </link>
  <joint
    name="left_wrist_roll_joint"
    type="revolute">
    <origin
      xyz="0.1 0.0019 -0.009"
      rpy="0 0 0" />
    <parent
      link="left_elbow_link" />
    <child
      link="left_wrist_roll_link" />
    <axis
      xyz="1 0 0" />
    <limit
      lower="-2.2253"
      upper="2.2253"
      effort="9.775"
      velocity="3.1416" />
  </joint>
  <link
    name="left_wrist_pitch_link">
    <inertial>
      <origin
        xyz="0.05147 0.00191 0.00656"
        rpy="0 0 0" />
      <mass
        value="0.38948" />
      <inertia
        ixx="0.00015"
        ixy="-3E-05"
        ixz="1E-05"
        iyy="0.00017"
        iyz="0"
        izz="0.00019" />
    </inertial>
    <visual>
      <origin
        xyz="0 0 0"
        rpy="0 0 0" />
      <geometry>
        <mesh
          filename="package://whole_v1.1_u1.0_1125/meshes/left_wrist_pitch_link.STL" />
      </geometry>
      <material
        name="">
        <color
          rgba="0.75294 0.75294 0.75294 1" />
      </material>
    </visual>
    <collision>
      <origin
        xyz="0 0 0"
        rpy="0 0 0" />
      <geometry>
        <mesh
          filename="package://whole_v1.1_u1.0_1125/meshes/left_wrist_pitch_link.STL" />
      </geometry>
    </collision>
  </link>
  <joint
    name="left_wrist_pitch_joint"
    type="revolute">
    <origin
      xyz="0.1135 0 0"
      rpy="0 0 0" />
    <parent
      link="left_wrist_roll_link" />
    <child
      link="left_wrist_pitch_link" />
    <axis
      xyz="0 1 0" />
    <limit
      lower="-0.2448"
      upper="0.2448"
      effort="9.775"
      velocity="3.1416" />
  </joint>
  <link
    name="left_wrist_yaw_link">
    <inertial>
      <origin
        xyz="0.11315 -0.00842 0.01032"
        rpy="0 0 0" />
      <mass
        value="0.54499" />
      <inertia
        ixx="0.00059"
        ixy="5E-05"
        ixz="-0.00016"
        iyy="0.00176"
        iyz="-0.00017"
        izz="0.00158" />
    </inertial>
    <visual>
      <origin
        xyz="0 0 0"
        rpy="0 0 0" />
      <geometry>
        <mesh
          filename="package://whole_v1.1_u1.0_1125/meshes/left_wrist_yaw_link.STL" />
      </geometry>
      <material
        name="">
        <color
          rgba="0.75294 0.75294 0.75294 1" />
      </material>
    </visual>
    <collision>
      <origin
        xyz="0 0 0"
        rpy="0 0 0" />
      <geometry>
        <mesh
          filename="package://whole_v1.1_u1.0_1125/meshes/left_wrist_yaw_link.STL" />
      </geometry>
    </collision>
  </link>
  <joint
    name="left_wrist_yaw_joint"
    type="revolute">
    <origin
      xyz="0.054 0 0"
      rpy="0 0 0" />
    <parent
      link="left_wrist_pitch_link" />
    <child
      link="left_wrist_yaw_link" />
    <axis
      xyz="0 0 1" />
    <limit
      lower="-0.5637"
      upper="0.5637"
      effort="9.775"
      velocity="3.1416" />
  </joint>
  <link
    name="right_shoulder_pitch_link">
    <inertial>
      <origin
        xyz="0.00548 -0.04522 0"
        rpy="0 0 0" />
      <mass
        value="0.80733" />
      <inertia
        ixx="0.00057"
        ixy="0"
        ixz="0"
        iyy="0.00056"
        iyz="0"
        izz="0.00059" />
    </inertial>
    <visual>
      <origin
        xyz="0 0 0"
        rpy="0 0 0" />
      <geometry>
        <mesh
          filename="package://whole_v1.1_u1.0_1125/meshes/right_shoulder_pitch_link.STL" />
      </geometry>
      <material
        name="">
        <color
          rgba="0.75294 0.75294 0.75294 1" />
      </material>
    </visual>
    <collision>
      <origin
        xyz="0 0 0"
        rpy="0 0 0" />
      <geometry>
        <mesh
          filename="package://whole_v1.1_u1.0_1125/meshes/right_shoulder_pitch_link.STL" />
      </geometry>
    </collision>
  </link>
  <joint
    name="right_shoulder_pitch_joint"
    type="revolute">
    <origin
      xyz="0 -0.1446 0.3935"
      rpy="0 0 0" />
    <parent
      link="waist_pitch_link" />
    <child
      link="right_shoulder_pitch_link" />
    <axis
      xyz="0 1 0" />
    <limit
      lower="-2.2253"
      upper="2.2253"
      effort="68"
      velocity="2.618" />
  </joint>
  <link
    name="right_shoulder_roll_link">
    <inertial>
      <origin
        xyz="0.00427 -7E-05 -0.09705"
        rpy="0 0 0" />
      <mass
        value="0.88811" />
      <inertia
        ixx="0.0013"
        ixy="0"
        ixz="0.0003"
        iyy="0.00145"
        iyz="0"
        izz="0.00085" />
    </inertial>
    <visual>
      <origin
        xyz="0 0 0"
        rpy="0 0 0" />
      <geometry>
        <mesh
          filename="package://whole_v1.1_u1.0_1125/meshes/right_shoulder_roll_link.STL" />
      </geometry>
      <material
        name="">
        <color
          rgba="0.75294 0.75294 0.75294 1" />
      </material>
    </visual>
    <collision>
      <origin
        xyz="0 0 0"
        rpy="0 0 0" />
      <geometry>
        <mesh
          filename="package://whole_v1.1_u1.0_1125/meshes/right_shoulder_roll_link.STL" />
      </geometry>
    </collision>
  </link>
  <joint
    name="right_shoulder_roll_joint"
    type="revolute">
    <origin
      xyz="0 -0.047 0"
      rpy="0 0 0" />
    <parent
      link="right_shoulder_pitch_link" />
    <child
      link="right_shoulder_roll_link" />
    <axis
      xyz="1 0 0" />
    <limit
      lower="-2.5962"
      upper="0"
      effort="68"
      velocity="2.618" />
  </joint>
  <link
    name="right_shoulder_yaw_link">
    <inertial>
      <origin
        xyz="0.00626 -0.00767 -0.09172"
        rpy="0 0 0" />
      <mass
        value="0.99118" />
      <inertia
        ixx="0.00138"
        ixy="-1E-05"
        ixz="-7E-05"
        iyy="0.00141"
        iyz="8E-05"
        izz="0.00079" />
    </inertial>
    <visual>
      <origin
        xyz="0 0 0"
        rpy="0 0 0" />
      <geometry>
        <mesh
          filename="package://whole_v1.1_u1.0_1125/meshes/right_shoulder_yaw_link.STL" />
      </geometry>
      <material
        name="">
        <color
          rgba="0.75294 0.75294 0.75294 1" />
      </material>
    </visual>
    <collision>
      <origin
        xyz="0 0 0"
        rpy="0 0 0" />
      <geometry>
        <mesh
          filename="package://whole_v1.1_u1.0_1125/meshes/right_shoulder_yaw_link.STL" />
      </geometry>
    </collision>
  </link>
  <joint
    name="right_shoulder_yaw_joint"
    type="revolute">
    <origin
      xyz="-0.00072034 0 -0.1346"
      rpy="0 0 0" />
    <parent
      link="right_shoulder_roll_link" />
    <child
      link="right_shoulder_yaw_link" />
    <axis
      xyz="0 0 1" />
    <limit
      lower="-0.2225"
      upper="0.2225"
      effort="68"
      velocity="3.1416" />
  </joint>
  <link
    name="right_elbow_link">
    <inertial>
      <origin
        xyz="0.08085 -0.01096 -0.00843"
        rpy="0 0 0" />
      <mass
        value="0.54056" />
      <inertia
        ixx="0.00037"
        ixy="0.0002"
        ixz="-2E-05"
        iyy="0.0006"
        iyz="-1E-05"
        izz="0.00077" />
    </inertial>
    <visual>
      <origin
        xyz="0 0 0"
        rpy="0 0 0" />
      <geometry>
        <mesh
          filename="package://whole_v1.1_u1.0_1125/meshes/right_elbow_link.STL" />
      </geometry>
      <material
        name="">
        <color
          rgba="0.75294 0.75294 0.75294 1" />
      </material>
    </visual>
    <collision>
      <origin
        xyz="0 0 0"
        rpy="0 0 0" />
      <geometry>
        <mesh
          filename="package://whole_v1.1_u1.0_1125/meshes/right_elbow_link.STL" />
      </geometry>
    </collision>
  </link>
  <joint
    name="right_elbow_joint"
    type="revolute">
    <origin
      xyz="0.0075 0 -0.1019"
      rpy="0 0 0" />
    <parent
      link="right_shoulder_yaw_link" />
    <child
      link="right_elbow_link" />
    <axis
      xyz="0 1 0" />
    <limit
      lower="-0.5934"
      upper="2.8187"
      effort="68"
      velocity="3.1416" />
  </joint>
  <link
    name="right_wrist_roll_link">
    <inertial>
      <origin
        xyz="0.08528 -0.00514 -5E-05"
        rpy="0 0 0" />
      <mass
        value="0.67942" />
      <inertia
        ixx="0.00044"
        ixy="-0.0001"
        ixz="0"
        iyy="0.00106"
        iyz="0"
        izz="0.00115" />
    </inertial>
    <visual>
      <origin
        xyz="0 0 0"
        rpy="0 0 0" />
      <geometry>
        <mesh
          filename="package://whole_v1.1_u1.0_1125/meshes/right_wrist_roll_link.STL" />
      </geometry>
      <material
        name="">
        <color
          rgba="0.75294 0.75294 0.75294 1" />
      </material>
    </visual>
    <collision>
      <origin
        xyz="0 0 0"
        rpy="0 0 0" />
      <geometry>
        <mesh
          filename="package://whole_v1.1_u1.0_1125/meshes/right_wrist_roll_link.STL" />
      </geometry>
    </collision>
  </link>
  <joint
    name="right_wrist_roll_joint"
    type="revolute">
    <origin
      xyz="0.1 -0.0019 -0.009"
      rpy="0 0 0" />
    <parent
      link="right_elbow_link" />
    <child
      link="right_wrist_roll_link" />
    <axis
      xyz="1 0 0" />
    <limit
      lower="-2.2253"
      upper="2.2253"
      effort="9.775"
      velocity="3.1416" />
  </joint>
  <link
    name="right_wrist_pitch_link">
    <inertial>
      <origin
        xyz="0.05147 -0.00191 0.00656"
        rpy="0 0 0" />
      <mass
        value="0.38948" />
      <inertia
        ixx="0.00015"
        ixy="3E-05"
        ixz="1E-05"
        iyy="0.00017"
        iyz="0"
        izz="0.00019" />
    </inertial>
    <visual>
      <origin
        xyz="0 0 0"
        rpy="0 0 0" />
      <geometry>
        <mesh
          filename="package://whole_v1.1_u1.0_1125/meshes/right_wrist_pitch_link.STL" />
      </geometry>
      <material
        name="">
        <color
          rgba="0.75294 0.75294 0.75294 1" />
      </material>
    </visual>
    <collision>
      <origin
        xyz="0 0 0"
        rpy="0 0 0" />
      <geometry>
        <mesh
          filename="package://whole_v1.1_u1.0_1125/meshes/right_wrist_pitch_link.STL" />
      </geometry>
    </collision>
  </link>
  <joint
    name="right_wrist_pitch_joint"
    type="revolute">
    <origin
      xyz="0.1135 0 0"
      rpy="0 0 0" />
    <parent
      link="right_wrist_roll_link" />
    <child
      link="right_wrist_pitch_link" />
    <axis
      xyz="0 1 0" />
    <limit
      lower="-0.2448"
      upper="0.2448"
      effort="9.775"
      velocity="3.1416" />
  </joint>
  <link
    name="right_wrist_yaw_link">
    <inertial>
      <origin
        xyz="0.11316 0.00842 0.01033"
        rpy="0 0 0" />
      <mass
        value="0.54499" />
      <inertia
        ixx="0.00059"
        ixy="-5E-05"
        ixz="-0.00016"
        iyy="0.00176"
        iyz="0.00017"
        izz="0.00158" />
    </inertial>
    <visual>
      <origin
        xyz="0 0 0"
        rpy="0 0 0" />
      <geometry>
        <mesh
          filename="package://whole_v1.1_u1.0_1125/meshes/right_wrist_yaw_link.STL" />
      </geometry>
      <material
        name="">
        <color
          rgba="0.75294 0.75294 0.75294 1" />
      </material>
    </visual>
    <collision>
      <origin
        xyz="0 0 0"
        rpy="0 0 0" />
      <geometry>
        <mesh
          filename="package://whole_v1.1_u1.0_1125/meshes/right_wrist_yaw_link.STL" />
      </geometry>
    </collision>
  </link>
  <joint
    name="right_wrist_yaw_joint"
    type="revolute">
    <origin
      xyz="0.054 0 0"
      rpy="0 0 0" />
    <parent
      link="right_wrist_pitch_link" />
    <child
      link="right_wrist_yaw_link" />
    <axis
      xyz="0 0 1" />
    <limit
      lower="-0.5637"
      upper="0.5637"
      effort="9.775"
      velocity="3.1416" />
  </joint>
</robot>