<?xml version="1.0" encoding="utf-8"?>
<!-- This URDF was automatically created by SolidWorks to URDF Exporter! Originally created by Stephen Brawner (brawner@gmail.com) 
     Commit Version: 1.6.0-4-g7f85cfe  Build Version: 1.6.7995.38578
     For more information, please see http://wiki.ros.org/sw_urdf_exporter -->
<robot
  name="v1.1_Whole_u2.1_0114">
  <mujoco>
    <compiler
    	meshdir="meshes/"
    	balanceinertia="true"
    	discardvisual="false" />
  </mujoco>

  <!-- <link name="world"> </link>
  
  <joint name="floating_base_joint" type="floating">
    <parent link="world"/>
    <child link="base_link"/> 
  </joint> -->
  <link
    name="base_link">
    <inertial>
      <origin
        xyz="-0.000112 5E-06 -0.049468"
        rpy="0 0 0" />
      <mass
        value="5.611522" />
      <inertia
        ixx="0.027821"
        ixy="0"
        ixz="1.4E-05"
        iyy="0.018827"
        iyz="1E-06"
        izz="0.0298" />
    </inertial>
    <visual>
      <origin
        xyz="0 0 0"
        rpy="0 0 0" />
      <geometry>
        <mesh
          filename="./meshes/base_link.STL" />
      </geometry>
      <material
        name="">
        <color
          rgba="0.75294 0.75294 0.75294 1" />
      </material>
    </visual>
    <!-- <collision>
      <origin
        xyz="0 0 0"
        rpy="0 0 0" />
      <geometry>
        <mesh
          filename="./meshes/base_link.STL" />
      </geometry>
    </collision> -->
    <collision>
      <origin
        xyz="0.00 0 -0.04"
        rpy="0 0 0" />
      <geometry>
               <box size="0.1 0.2 0.05"/> 
      </geometry>
    </collision>
  </link>
  <link
    name="left_hip_pitch_link">
    <inertial>
      <origin
        xyz="0.0036335 0.021596 -0.028209"
        rpy="0 0 0" />
      <mass
        value="2.2348695" />
      <inertia
        ixx="0.005122"
        ixy="0.000167"
        ixz="-0.000025"
        iyy="0.004033"
        iyz="-0.000245"
        izz="0.0042625" />
    </inertial>
    <visual>
      <origin
        xyz="0 0 0"
        rpy="0 0 0" />
      <geometry>
        <mesh
          filename="./meshes/left_hip_pitch_link.STL" />
      </geometry>
      <material
        name="">
        <color
          rgba="0.752941176470588 0.752941176470588 0.752941176470588 1" />
      </material>
    </visual>
    <!-- <collision>
      <origin
        xyz="0 0 0"
        rpy="0 0 0" />
      <geometry>
        <mesh
          filename="./meshes/left_hip_pitch_link.STL" />
      </geometry>
    </collision> -->
    <collision>
      <origin
        xyz="0 0.0 -0."
        rpy="1.57 0 0" />
      <geometry>
        <cylinder radius="0.04" length="0.06"/>
      </geometry>
    </collision>
  </link>
  <joint
    name="left_hip_pitch_joint"
    type="revolute">
    <origin
      xyz="0 0.11619 -0.12455"
      rpy="-0.7854 0 0" />
    <parent
      link="base_link" />
    <child
      link="left_hip_pitch_link" />
    <axis
      xyz="0 1 0" />
    <limit
      lower="-1.0777"
      upper="1.4094"
      effort="142.5000"
      velocity="13.0900" />
  </joint>
  <link
    name="left_hip_roll_link">
    <inertial>
      <origin
        xyz="0.001506 0.0000155 -0.084234"
        rpy="0 0 0" />
      <mass
        value="1.458551" />
      <inertia
        ixx="0.003049"
        ixy="0"
        ixz="0.000187"
        iyy="0.0044765"
        iyz="0"
        izz="0.003191" />
    </inertial>
    <visual>
      <origin
        xyz="0 0 0"
        rpy="0 0 0" />
      <geometry>
        <mesh
          filename="./meshes/left_hip_roll_link.STL" />
      </geometry>
      <material
        name="">
        <color
          rgba="0.75294 0.75294 0.75294 1" />
      </material>
    </visual>
    <!-- <collision>
      <origin
        xyz="0 0 0"
        rpy="0 0 0" />
      <geometry>
        <mesh
          filename="./meshes/left_hip_roll_link.STL" />
      </geometry>
    </collision> -->
    <collision>
        <origin
        xyz="-0.00 0 -0.06"
        rpy="0 0.0 0" />
      <geometry>
        <cylinder radius="0.05" length="0.1"/>  

      </geometry>
    </collision>
  </link>
  <joint
    name="left_hip_roll_joint"
    type="revolute">
    <origin
      xyz="-0.001 0.03 -0.03"
      rpy="0.7854 0 0" />
    <parent
      link="left_hip_pitch_link" />
    <child
      link="left_hip_roll_link" />
    <axis
      xyz="1 0 0" />
    <limit
      lower="-0.7461"
      upper="0.7461"
      effort="142.5000"
      velocity="13.0900" />
  </joint>
  <link
    name="left_hip_yaw_link">
    <inertial>
      <origin
        xyz="-0.010707 -0.0086045 -0.12044"
        rpy="0 0 0" />
      <mass
        value="2.321537" />
      <inertia
        ixx="0.0087775"
        ixy="0.000065"
        ixz="0.000750"
        iyy="0.009588"
        iyz="0.000677"
        izz="0.003117" />
    </inertial>
    <visual>
      <origin
        xyz="0 0 0"
        rpy="0 0 0" />
      <geometry>
        <mesh
          filename="./meshes/left_hip_yaw_link.STL" />
      </geometry>
      <material
        name="">
        <color
          rgba="0.752941176470588 0.752941176470588 0.752941176470588 1" />
      </material>
    </visual>
    <collision>
      <origin
        xyz="0 0 0"
        rpy="0 0 0" />
      <geometry>
        <mesh
          filename="./meshes/left_hip_yaw_link.STL" />
      </geometry>
    </collision>
  </link>
  <joint
    name="left_hip_yaw_joint"
    type="revolute">
    <origin
      xyz="0 0 -0.13"
      rpy="0 0 0" />
    <parent
      link="left_hip_roll_link" />
    <child
      link="left_hip_yaw_link" />
    <axis
      xyz="0 0 1" />
    <limit
      lower="-1.9897"
      upper="1.9897"
      effort="85.5000"
      velocity="13.0900" />
  </joint>
  <link
    name="left_knee_link">
    <inertial>
      <origin
        xyz="0.0036595 0.0002655 -0.139092"
        rpy="0 0 0" />
      <mass
        value="1.737676" />
      <inertia
        ixx="0.010164"
        ixy="-0.000002"
        ixz="-0.000155"
        iyy="0.0096415"
        iyz="0.000033"
        izz="0.001831" />
    </inertial>
    <visual>
      <origin
        xyz="0 0 0"
        rpy="0 0 0" />
      <geometry>
        <mesh
          filename="./meshes/left_knee_link.STL" />
      </geometry>
      <material
        name="">
        <color
          rgba="0.75294 0.75294 0.75294 1" />
      </material>
    </visual>
    <!-- <collision>
      <origin
        xyz="0 0 0"
        rpy="0 0 0" />
      <geometry>
        <mesh
          filename="./meshes/left_knee_link.STL" />
      </geometry>
    </collision> -->
    <collision>
      <origin
        xyz="0.01 0.00 -0.2"
        rpy="0 0 0" />
      <geometry>
        <cylinder radius="0.04" length="0.23"/>
      </geometry>
    </collision>
  </link>
  <joint
    name="left_knee_joint"
    type="revolute">
    <origin
      xyz="-0.015 0 -0.151"
      rpy="0 0 0" />
    <parent
      link="left_hip_yaw_link" />
    <child
      link="left_knee_link" />
    <axis
      xyz="0 1 0" />
    <limit
      lower="0"
      upper="1.9897"
      effort="142.5000"
      velocity="13.0900" />
  </joint>
  <link
    name="left_ankle_pitch_link">
    <inertial>
      <origin
        xyz="-0.0025805 -0.0005255 -0.0075905"
        rpy="0 0 0" />
      <mass
        value="0.0744505" />
      <inertia
        ixx="0.0000125"
        ixy="0"
        ixz="0.000002"
        iyy="0.000013"
        iyz="0"
        izz="0.000014" />
    </inertial>
    <visual>
      <origin
        xyz="0 0 0"
        rpy="0 0 0" />
      <geometry>
        <mesh
          filename="./meshes/left_ankle_pitch_link.STL" />
      </geometry>
      <material
        name="">
        <color
          rgba="0.752941176470588 0.752941176470588 0.752941176470588 1" />
      </material>
    </visual>
    <!-- <collision>
      <origin
        xyz="0 0 0"
        rpy="0 0 0" />
      <geometry>
        <mesh
          filename="./meshes/left_ankle_pitch_link.STL" />
      </geometry>
    </collision> -->
  </link>
  <joint
    name="left_ankle_pitch_joint"
    type="revolute">
    <origin
      xyz="0.015 0.0005 -0.339"
      rpy="0 0 0" />
    <parent
      link="left_knee_link" />
    <child
      link="left_ankle_pitch_link" />
    <axis
      xyz="0 1 0" />
    <limit
      lower="-0.8125"
      upper="0.2487"
      effort="51.3"
      velocity="7.0162" />
  </joint>
  <link
    name="left_ankle_roll_link">
    <inertial>
      <origin
        xyz="0.0448195 -3.2E-05 -0.0354495"
        rpy="0 0 0" />
      <mass
        value="0.8328245" />
      <inertia
        ixx="0.000534"
        ixy="0.000001"
        ixz="-0.000298"
        iyy="0.0042065"
        iyz="-0.000001"
        izz="0.0042605" />
    </inertial>
    <visual>
      <origin
        xyz="0 0 0"
        rpy="0 0 0" />
      <geometry>
        <mesh
          filename="./meshes/left_ankle_roll_link.STL" />
      </geometry>
      <material
        name="">
        <color
          rgba="0.752941176470588 0.752941176470588 0.752941176470588 1" />
      </material>
    </visual>
    <!-- <collision>
      <origin
        xyz="0 0 0"
        rpy="0 0 0" />
      <geometry>
        <mesh
          filename="./meshes/left_ankle_roll_link.STL" />
      </geometry>
    </collision> -->
    <collision>
      <origin xyz="-0.06 0.035 -0.06" rpy="0 0 0"/>
      <geometry>
        <sphere radius="0.005"/>
      </geometry>
    </collision>
    <collision>
      <origin xyz="-0.06 -0.035 -0.06" rpy="0 0 0"/>
      <geometry>
        <sphere radius="0.005"/>
      </geometry>
    </collision>
    <collision>
      <origin xyz="0.13 0.035 -0.06" rpy="0 0 0"/>
      <geometry>
        <sphere radius="0.005"/>
      </geometry>
    </collision>
    <collision>
      <origin xyz="0.13 -0.035 -0.06" rpy="0 0 0"/>
      <geometry>
        <sphere radius="0.005"/>
      </geometry>
    </collision>

  <!-- 额外点 -->
    <collision>
      <origin xyz="0.17 0.018 -0.058" rpy="0 0 0"/>
      <geometry>
        <sphere radius="0.005"/>
      </geometry>
    </collision>
    <collision>
      <origin xyz="0.17 -0.018 -0.058" rpy="0 0 0"/>
      <geometry>
        <sphere radius="0.005"/>
      </geometry>
    </collision>

    <collision>
      <origin xyz="-0.035 0.035 -0.06" rpy="0 0 0"/>
      <geometry>
        <sphere radius="0.005"/>
      </geometry>
    </collision>
    <collision>
      <origin xyz="-0.035 -0.035 -0.06" rpy="0 0 0"/>
      <geometry>
        <sphere radius="0.005"/>
      </geometry>
    </collision>

    <collision>
      <origin xyz="0.06 0.035 -0.06" rpy="0 0 0"/>
      <geometry>
        <sphere radius="0.005"/>
      </geometry>
    </collision>
    <collision>
      <origin xyz="0.06 -0.035 -0.06" rpy="0 0 0"/>
      <geometry>
        <sphere radius="0.005"/>
      </geometry>
    </collision>
  </link>
  <joint
    name="left_ankle_roll_joint"
    type="revolute">
    <origin
      xyz="0 0 -0.015"
      rpy="0 0 0" />
    <parent
      link="left_ankle_pitch_link" />
    <child
      link="left_ankle_roll_link" />
    <axis
      xyz="1 0 0" />
    <limit
      lower="-0.1658"
      upper="0.1658"
      effort="51.3"
      velocity="7.0162" />
  </joint>
  <link
    name="right_hip_pitch_link">
    <inertial>
      <origin
        xyz="0.0036335 -0.021596 -0.028209"
        rpy="0 0 0" />
      <mass
        value="2.2348695" />
      <inertia
        ixx="0.005122"
        ixy="-0.000174"
        ixz="-0.000019"
        iyy="0.004033"
        iyz="0.000243"
        izz="0.0042625" />
    </inertial>
    <visual>
      <origin
        xyz="0 0 0"
        rpy="0 0 0" />
      <geometry>
        <mesh
          filename="./meshes/right_hip_pitch_link.STL" />
      </geometry>
      <material
        name="">
        <color
          rgba="0.752941176470588 0.752941176470588 0.752941176470588 1" />
      </material>
    </visual>
    <!-- <collision>
      <origin
        xyz="0 0 0"
        rpy="0 0 0" />
      <geometry>
        <mesh
          filename="./meshes/right_hip_pitch_link.STL" />
      </geometry>
    </collision> -->
    <collision>
      <origin
        xyz="0 0.0 -0."
        rpy="1.57 0 0" />
      <geometry>
        <cylinder radius="0.04" length="0.06"/>
      </geometry>
    </collision>
  </link>
  <joint
    name="right_hip_pitch_joint"
    type="revolute">
    <origin
      xyz="0 -0.11619 -0.12455"
      rpy="0.7854 0 0" />
    <parent
      link="base_link" />
    <child
      link="right_hip_pitch_link" />
    <axis
      xyz="0 1 0" />
    <limit
      lower="-1.0777"
      upper="1.4094"
      effort="142.5"
      velocity="13.0900" />
  </joint>
  <link
    name="right_hip_roll_link">
    <inertial>
      <origin
        xyz="0.001506 -0.0000155 -0.084234"
        rpy="0 0 0" />
      <mass
        value="1.458551" />
      <inertia
        ixx="0.003049"
        ixy="0.000012"
        ixz="0.000187"
        iyy="0.0044765"
        iyz="0.000001"
        izz="0.003191" />
    </inertial>
    <visual>
      <origin
        xyz="0 0 0"
        rpy="0 0 0" />
      <geometry>
        <mesh
          filename="./meshes/right_hip_roll_link.STL" />
      </geometry>
      <material
        name="">
        <color
          rgba="0.752941176470588 0.752941176470588 0.752941176470588 1" />
      </material>
    </visual>
    <!-- <collision>
      <origin
        xyz="0 0 0"
        rpy="0 0 0" />
      <geometry>
        <mesh
          filename="./meshes/right_hip_roll_link.STL" />
      </geometry>
    </collision> -->
    <collision>
        <origin
        xyz="-0.00 0 -0.06"
        rpy="0 0.0 0" />
      <geometry>
        <cylinder radius="0.05" length="0.1"/>  
      </geometry>
    </collision>
  </link>
  <joint
    name="right_hip_roll_joint"
    type="revolute">
    <origin
      xyz="-0.001 -0.03 -0.03"
      rpy="-0.7854 0 0" />
    <parent
      link="right_hip_pitch_link" />
    <child
      link="right_hip_roll_link" />
    <axis
      xyz="1 0 0" />
    <limit
      lower="-0.7461"
      upper="0.7461"
      effort="142.5"
      velocity="13.0900" />
  </joint>
  <link
    name="right_hip_yaw_link">
    <inertial>
      <origin
        xyz="-0.010707 0.0086045 -0.12044"
        rpy="0 0 0" />
      <mass
        value="2.321537" />
      <inertia
        ixx="0.0087775"
        ixy="-0.000066"
        ixz="0.000751"
        iyy="0.009588"
        iyz="-0.000671"
        izz="0.003117" />
    </inertial>
    <visual>
      <origin
        xyz="0 0 0"
        rpy="0 0 0" />
      <geometry>
        <mesh
          filename="./meshes/right_hip_yaw_link.STL" />
      </geometry>
      <material
        name="">
        <color
          rgba="0.752941176470588 0.752941176470588 0.752941176470588 1" />
      </material>
    </visual>
    <collision>
      <origin
        xyz="0 0 0"
        rpy="0 0 0" />
      <geometry>
        <mesh
          filename="./meshes/right_hip_yaw_link.STL" />
      </geometry>
    </collision>
  </link>
  <joint
    name="right_hip_yaw_joint"
    type="revolute">
    <origin
      xyz="0 0 -0.13"
      rpy="0 0 0" />
    <parent
      link="right_hip_roll_link" />
    <child
      link="right_hip_yaw_link" />
    <axis
      xyz="0 0 1" />
    <limit
      lower="-1.9897"
      upper="1.9897"
      effort="85.5"
      velocity="13.0900" />
  </joint>
  <link
    name="right_knee_link">
    <inertial>
      <origin
        xyz="0.0036595 -0.0002655 -0.139092"
        rpy="0 0 0" />
      <mass
        value="1.737676" />
      <inertia
        ixx="0.010164"
        ixy="0.000002"
        ixz="-0.000176"
        iyy="0.0096415"
        iyz="-0.000031"
        izz="0.001831" />
    </inertial>
    <visual>
      <origin
        xyz="0 0 0"
        rpy="0 0 0" />
      <geometry>
        <mesh
          filename="./meshes/right_knee_link.STL" />
      </geometry>
      <material
        name="">
        <color
          rgba="0.752941176470588 0.752941176470588 0.752941176470588 1" />
      </material>
    </visual>
    <!-- <collision>
      <origin
        xyz="0 0 0"
        rpy="0 0 0" />
      <geometry>
        <mesh
          filename="./meshes/right_knee_link.STL" />
      </geometry>
    </collision> -->
    <collision>
      <origin
        xyz="0.01 0.00 -0.2"
        rpy="0 0 0" />
      <geometry>
        <cylinder radius="0.04" length="0.23"/>
      </geometry>
    </collision>
  </link>
  <joint
    name="right_knee_joint"
    type="revolute">
    <origin
      xyz="-0.015 0 -0.151"
      rpy="0 0 0" />
    <parent
      link="right_hip_yaw_link" />
    <child
      link="right_knee_link" />
    <axis
      xyz="0 1 0" />
    <limit
      lower="0"
      upper="1.9897"
      effort="142.5"
      velocity="13.0900" />
  </joint>
  <link
    name="right_ankle_pitch_link">
    <inertial>
      <origin
        xyz="-0.0025805 0.0005255 -0.0075905"
        rpy="0 0 0" />
      <mass
        value="0.0744505" />
      <inertia
        ixx="0.0000125"
        ixy="0"
        ixz="0.000001"
        iyy="0.000013"
        iyz="0"
        izz="0.000014" />
    </inertial>
    <visual>
      <origin
        xyz="0 0 0"
        rpy="0 0 0" />
      <geometry>
        <mesh
          filename="./meshes/right_ankle_pitch_link.STL" />
      </geometry>
      <material
        name="">
        <color
          rgba="0.752941176470588 0.752941176470588 0.752941176470588 1" />
      </material>
    </visual>
    <!-- <collision>
      <origin
        xyz="0 0 0"
        rpy="0 0 0" />
      <geometry>
        <mesh
          filename="./meshes/right_ankle_pitch_link.STL" />
      </geometry>
    </collision> -->
  </link>
  <joint
    name="right_ankle_pitch_joint"
    type="revolute">
    <origin
      xyz="0.015 -0.0005 -0.339"
      rpy="0 0 0" />
    <parent
      link="right_knee_link" />
    <child
      link="right_ankle_pitch_link" />
    <axis
      xyz="0 1 0" />
    <limit
      lower="-0.8125"
      upper="0.2487"
      effort="51.3"
      velocity="7.0162" />
  </joint>
  <link
    name="right_ankle_roll_link">
    <inertial>
      <origin
        xyz="0.0448195 3.2E-05 -0.0354495"
        rpy="0 0 0" />
      <mass
        value="0.8328245" />
      <inertia
        ixx="0.000534"
        ixy="-0.000001"
        ixz="-0.000291"
        iyy="0.0042065"
        iyz="0.000001"
        izz="0.0042605" />
    </inertial>
    <visual>
      <origin
        xyz="0 0 0"
        rpy="0 0 0" />
      <geometry>
        <mesh
          filename="./meshes/right_ankle_roll_link.STL" />
      </geometry>
      <material
        name="">
        <color
          rgba="0.752941176470588 0.752941176470588 0.752941176470588 1" />
      </material>
    </visual>
    <!-- <collision>
      <origin
        xyz="0 0 0"
        rpy="0 0 0" />
      <geometry>
        <mesh
          filename="./meshes/right_ankle_roll_link.STL" />
      </geometry>
    </collision> -->
    <collision>
      <origin xyz="-0.06 0.035 -0.06" rpy="0 0 0"/>
      <geometry>
        <sphere radius="0.005"/>
      </geometry>
    </collision>
    <collision>
      <origin xyz="-0.06 -0.035 -0.06" rpy="0 0 0"/>
      <geometry>
        <sphere radius="0.005"/>
      </geometry>
    </collision>
    <collision>
      <origin xyz="0.13 0.035 -0.06" rpy="0 0 0"/>
      <geometry>
        <sphere radius="0.005"/>
      </geometry>
    </collision>
    <collision>
      <origin xyz="0.13 -0.035 -0.06" rpy="0 0 0"/>
      <geometry>
        <sphere radius="0.005"/>
      </geometry>
    </collision>

  <!-- 额外点  可关闭-->
    <collision>
      <origin xyz="0.17 0.018 -0.058" rpy="0 0 0"/>
      <geometry>
        <sphere radius="0.005"/>
      </geometry>
    </collision>
    <collision>
      <origin xyz="0.17 -0.018 -0.058" rpy="0 0 0"/>
      <geometry>
        <sphere radius="0.005"/>
      </geometry>
    </collision>

    <collision>
      <origin xyz="-0.035 0.035 -0.06" rpy="0 0 0"/>
      <geometry>
        <sphere radius="0.005"/>
      </geometry>
    </collision>
    <collision>
      <origin xyz="-0.035 -0.035 -0.06" rpy="0 0 0"/>
      <geometry>
        <sphere radius="0.005"/>
      </geometry>
    </collision>

    <collision>
      <origin xyz="0.06 0.035 -0.06" rpy="0 0 0"/>
      <geometry>
        <sphere radius="0.005"/>
      </geometry>
    </collision>
    <collision>
      <origin xyz="0.06 -0.035 -0.06" rpy="0 0 0"/>
      <geometry>
        <sphere radius="0.005"/>
      </geometry>
    </collision>
  </link>
  <joint
    name="right_ankle_roll_joint"
    type="revolute">
    <origin
      xyz="0 0 -0.015"
      rpy="0 0 0" />
    <parent
      link="right_ankle_pitch_link" />
    <child
      link="right_ankle_roll_link" />
    <axis
      xyz="1 0 0" />
    <limit
      lower="-0.1658"
      upper="0.1658"
      effort="51.3"
      velocity="7.0162" />
  </joint>
  <link
    name="waist_yaw_link">
    <inertial>
      <origin
        xyz="-0.025004 1E-06 0.041503"
        rpy="0 0 0" />
      <mass
        value="0.220887" />
      <inertia
        ixx="0.000153"
        ixy="0"
        ixz="-2.5E-05"
        iyy="0.000361"
        iyz="0"
        izz="0.000463" />
    </inertial>
    <visual>
      <origin
        xyz="0 0 0"
        rpy="0 0 0" />
      <geometry>
        <mesh
          filename="./meshes/waist_yaw_link.STL" />
      </geometry>
      <material
        name="">
        <color
          rgba="0.752941176470588 0.752941176470588 0.752941176470588 1" />
      </material>
    </visual>
    <!-- <collision>
      <origin
        xyz="0 0 0"
        rpy="0 0 0" />
      <geometry>
        <mesh
          filename="./meshes/waist_yaw_link.STL" />
      </geometry>
    </collision> -->
  </link>
  <joint
    name="waist_yaw_joint"
    type="revolute">
    <origin
      xyz="0 0 0"
      rpy="0 0 0" />
    <parent
      link="base_link" />
    <child
      link="waist_yaw_link" />
    <axis
      xyz="0 0 1" />
    <limit
      lower="-1.4923"
      upper="1.4923"
      effort="85.5"
      velocity="13.0900" />
  </joint>
  <link
    name="waist_roll_link">
    <inertial>
      <origin
        xyz="0 0 -0.000017"
        rpy="0 0 0" />
      <mass
        value="0.044979" />
      <inertia
        ixx="6E-06"
        ixy="0"
        ixz="0"
        iyy="0.000013"
        iyz="0"
        izz="0.000018" />
    </inertial>
    <visual>
      <origin
        xyz="0 0 0"
        rpy="0 0 0" />
      <geometry>
        <mesh
          filename="./meshes/waist_roll_link.STL" />
      </geometry>
      <material
        name="">
        <color
          rgba="0.752941176470588 0.752941176470588 0.752941176470588 1" />
      </material>
    </visual>
    <collision>
      <origin
        xyz="0 0 0"
        rpy="0 0 0" />
      <geometry>
        <mesh
          filename="./meshes/waist_roll_link.STL" />
      </geometry>
    </collision>
  </link>
  <joint
    name="waist_roll_joint"
    type="revolute">
    <origin
      xyz="0 0 0.0615"
      rpy="0 0 0" />
    <parent
      link="waist_yaw_link" />
    <child
      link="waist_roll_link" />
    <axis
      xyz="1 0 0" />
    <limit
      lower="-0.1658"
      upper="0.1658"
      effort="57"
      velocity="11.5192" />
  </joint>
  <link name="torso_link"> <!-- waist_pitch_link -->
    <inertial>
      <origin xyz="-0.005876 0.000112 0.233621" rpy="0 0 0" />
      <mass value="16.091591" />
      <inertia ixx="0.241494" ixy="-0.000033" ixz="0.004415" iyy="0.193478" iyz="-0.000333" izz="0.098354" />
    </inertial>
    <visual>
      <origin xyz="0 0 0" rpy="0 0 0" />
      <geometry>
        <mesh filename="./meshes/waist_pitch_link.STL" />
      </geometry>
      <material name="">
        <color rgba="0.752941176470588 0.752941176470588 0.752941176470588 1" />
      </material>
    </visual>
    <collision>
      <origin xyz="0 0 0" rpy="0 0 0" />
      <geometry>
        <mesh filename="./meshes/waist_pitch_link.STL" />
      </geometry>
    </collision>
  </link>
  <joint name="waist_pitch_joint" type="revolute">
    <origin xyz="0 0 0" rpy="0 0 0" />
    <parent link="waist_roll_link" />
    <child link="torso_link" /><!--waist_pitch_link -->
    <axis xyz="0 1 0" />
    <limit lower="-0.3316" upper="0.6632" effort="57" velocity="11.5192" />
  </joint>
  <link
    name="head_yaw_link">
    <inertial>
      <origin
        xyz="-0.001469 -0.001706 0.101301"
        rpy="0 0 0" />
      <mass
        value="0.879937" />
      <inertia
        ixx="0.002016"
        ixy="0.000020"
        ixz="0.000012"
        iyy="0.001837"
        iyz="-0.000019"
        izz="0.000719" />
    </inertial>
    <visual>
      <origin
        xyz="0 0 0"
        rpy="0 0 0" />
      <geometry>
        <mesh
          filename="./meshes/head_yaw_link.STL" />
      </geometry>
      <material
        name="">
        <color
          rgba="0.752941176470588 0.752941176470588 0.752941176470588 1" />
      </material>
    </visual>
    <collision>
      <origin
        xyz="0 0 0"
        rpy="0 0 0" />
      <geometry>
        <mesh
          filename="./meshes/head_yaw_link.STL" />
      </geometry>
    </collision>
  </link>
  <joint
    name="head_yaw_joint"
    type="fixed">
    <origin
      xyz="0 0 0.4375"
      rpy="0 0 0" />
    <parent
      link="torso_link" /><!-- waist_pitch_link -->
    <child
      link="head_yaw_link" />
    <axis
      xyz="0 0 1" />
    <limit
      lower="-1.4923"
      upper="1.4923"
      effort="13.3"
      velocity="27.2271" />
  </joint>
  <link
    name="head_pitch_link">
    <inertial>
      <origin
        xyz="0.024719 0.005163 0.054194"
        rpy="0 0 0" />
      <mass
        value="0.311827" />
      <inertia
        ixx="0.000474"
        ixy="-5.7E-05"
        ixz="-0.000221"
        iyy="0.000684"
        iyz="4E-06"
        izz="0.000504" />
    </inertial>
    <visual>
      <origin
        xyz="0 0 0"
        rpy="0 0 0" />
      <geometry>
        <mesh
          filename="./meshes/head_pitch_link.STL" />
      </geometry>
      <material
        name="">
        <color
          rgba="0.752941176470588 0.752941176470588 0.752941176470588 1" />
      </material>
    </visual>
    <collision>
      <origin
        xyz="0 0 0"
        rpy="0 0 0" />
      <geometry>
        <mesh
          filename="./meshes/head_pitch_link.STL" />
      </geometry>
    </collision>
  </link>
  <joint
    name="head_pitch_joint"
    type="fixed">
    <origin
      xyz="0 0 0.142"
      rpy="0 0 0" />
    <parent
      link="head_yaw_link" />
    <child
      link="head_pitch_link" />
    <axis
      xyz="0 1 0" />
    <limit
      lower="-0.6301"
      upper="0.2487"
      effort="13.3"
      velocity="27.2271" />
  </joint>
  <link
    name="left_shoulder_pitch_link">
    <inertial>
      <origin
        xyz="0.005572 0.0452205 -0.0000035"
        rpy="0 0 0" />
      <mass
        value="0.8091025" />
      <inertia
        ixx="0.0005705"
        ixy="2E-06"
        ixz="0"
        iyy="0.0005635"
        iyz="0"
        izz="0.0005935" />
    </inertial>
    <visual>
      <origin
        xyz="0 0 0"
        rpy="0 0 0" />
      <geometry>
        <mesh
          filename="./meshes/left_shoulder_pitch_link.STL" />
      </geometry>
      <material
        name="">
        <color
          rgba="0.752941176470588 0.752941176470588 0.752941176470588 1" />
      </material>
    </visual>
    <collision>
      <origin
        xyz="0 0 0"
        rpy="0 0 0" />
      <geometry>
        <mesh
          filename="./meshes/left_shoulder_pitch_link.STL" />
      </geometry>
    </collision>
  </link>
  <joint
    name="left_shoulder_pitch_joint"
    type="revolute">
    <origin
      xyz="0 0.1446 0.3935"
      rpy="0 0 0" />
    <parent
      link="torso_link" />
    <child
      link="left_shoulder_pitch_link" />
    <axis
      xyz="0 1 0" />
    <limit
      lower="-2.4871"
      upper="2.4871"
      effort="76"
      velocity="2.618" />
  </joint>
  <link
    name="left_shoulder_roll_link">
    <inertial>
      <origin
        xyz="0.004217 0.000064 -0.097176"
        rpy="0 0 0" />
      <mass
        value="0.8873675" />
      <inertia
        ixx="0.0012865"
        ixy="-0.000001"
        ixz="0.000284"
        iyy="0.0014345"
        iyz="0"
        izz="0.000849" />
    </inertial>
    <visual>
      <origin
        xyz="0 0 0"
        rpy="0 0 0" />
      <geometry>
        <mesh
          filename="./meshes/left_shoulder_roll_link.STL" />
      </geometry>
      <material
        name="">
        <color
          rgba="0.752941176470588 0.752941176470588 0.752941176470588 1" />
      </material>
    </visual>
    <collision>
      <origin
        xyz="0 0 0"
        rpy="0 0 0" />
      <geometry>
        <mesh
          filename="./meshes/left_shoulder_roll_link.STL" />
      </geometry>
    </collision>
  </link>
  <joint
    name="left_shoulder_roll_joint"
    type="revolute">
    <origin
      xyz="0 0.047 0"
      rpy="0 0 0" />
    <parent
      link="left_shoulder_pitch_link" />
    <child
      link="left_shoulder_roll_link" />
    <axis
      xyz="1 0 0" />
    <limit
      lower="0"
      upper="2.9016"
      effort="76"
      velocity="2.618" />
  </joint>
  <link
    name="left_shoulder_yaw_link">
    <inertial>
      <origin
        xyz="0.0062655 0.007667 -0.091717"
        rpy="0 0 0" />
      <mass
        value="0.9911815" />
      <inertia
        ixx="0.001378"
        ixy="0.000009"
        ixz="-0.000067"
        iyy="0.001411"
        iyz="-0.000075"
        izz="0.000788" />
    </inertial>
    <visual>
      <origin
        xyz="0 0 0"
        rpy="0 0 0" />
      <geometry>
        <mesh
          filename="./meshes/left_shoulder_yaw_link.STL" />
      </geometry>
      <material
        name="">
        <color
          rgba="0.752941176470588 0.752941176470588 0.752941176470588 1" />
      </material>
    </visual>
    <collision>
      <origin
        xyz="0 0 0"
        rpy="0 0 0" />
      <geometry>
        <mesh
          filename="./meshes/left_shoulder_yaw_link.STL" />
      </geometry>
    </collision>
  </link>
  <joint
    name="left_shoulder_yaw_joint"
    type="revolute">
    <origin
      xyz="-0.00072034 0 -0.1346"
      rpy="0 0 0" />
    <parent
      link="left_shoulder_roll_link" />
    <child
      link="left_shoulder_yaw_link" />
    <axis
      xyz="0 0 1" />
    <limit
      lower="-1.4915"
      upper="0.6629"
      effort="76"
      velocity="3.1416" />
  </joint>
  <link
    name="left_elbow_link">
    <inertial>
      <origin
        xyz="0.0811175 0.0108235 -0.0084595"
        rpy="0 0 0" />
      <mass
        value="0.538791" />
      <inertia
        ixx="0.0003675"
        ixy="-0.000190"
        ixz="-0.000022"
        iyy="0.0005905"
        iyz="0.000009"
        izz="0.0007565" />
    </inertial>
    <visual>
      <origin
        xyz="0 0 0"
        rpy="0 0 0" />
      <geometry>
        <mesh
          filename="./meshes/left_elbow_link.STL" />
      </geometry>
      <material
        name="">
        <color
          rgba="0.752941176470588 0.752941176470588 0.752941176470588 1" />
      </material>
    </visual>
    <collision>
      <origin
        xyz="0 0 0"
        rpy="0 0 0" />
      <geometry>
        <mesh
          filename="./meshes/left_elbow_link.STL" />
      </geometry>
    </collision>
  </link>
  <joint
    name="left_elbow_joint"
    type="revolute">
    <origin
      xyz="0.0075 0 -0.1019"
      rpy="0 0 0" />
    <parent
      link="left_shoulder_yaw_link" />
    <child
      link="left_elbow_link" />
    <axis
      xyz="0 1 0" />
    <limit
      lower="-0.6632"
      upper="3.1503"
      effort="76"
      velocity="3.1416" />
  </joint>
  <link
    name="left_wrist_roll_link">
    <inertial>
      <origin
        xyz="0.0852865 0.005134 -4.6E-05"
        rpy="0 0 0" />
      <mass
        value="0.679415" />
      <inertia
        ixx="0.0004425"
        ixy="0.000098"
        ixz="0"
        iyy="0.001056"
        iyz="0"
        izz="0.001146" />
    </inertial>
    <visual>
      <origin
        xyz="0 0 0"
        rpy="0 0 0" />
      <geometry>
        <mesh
          filename="./meshes/left_wrist_roll_link.STL" />
      </geometry>
      <material
        name="">
        <color
          rgba="0.752941176470588 0.752941176470588 0.752941176470588 1" />
      </material>
    </visual>
    <collision>
      <origin
        xyz="0 0 0"
        rpy="0 0 0" />
      <geometry>
        <mesh
          filename="./meshes/left_wrist_roll_link.STL" />
      </geometry>
    </collision>
  </link>
  <joint
    name="left_wrist_roll_joint"
    type="revolute">
    <origin
      xyz="0.1 0.0019 -0.009"
      rpy="0 0 0" />
    <parent
      link="left_elbow_link" />
    <child
      link="left_wrist_roll_link" />
    <axis
      xyz="1 0 0" />
    <limit
      lower="-2.4871"
      upper="2.4871"
      effort="10.9250"
      velocity="3.1416" />
  </joint>
  <link
    name="left_wrist_pitch_link">
    <inertial>
      <origin
        xyz="0.051473 0.001913 0.006559"
        rpy="0 0 0" />
      <mass
        value="0.389479" />
      <inertia
        ixx="0.000146"
        ixy="-0.000026"
        ixz="0.000007"
        iyy="0.000167"
        iyz="-0.000005"
        izz="0.000187" />
    </inertial>
    <visual>
      <origin
        xyz="0 0 0"
        rpy="0 0 0" />
      <geometry>
        <mesh
          filename="./meshes/left_wrist_pitch_link.STL" />
      </geometry>
      <material
        name="">
        <color
          rgba="0.752941176470588 0.752941176470588 0.752941176470588 1" />
      </material>
    </visual>
    <collision>
      <origin
        xyz="0 0 0"
        rpy="0 0 0" />
      <geometry>
        <mesh
          filename="./meshes/left_wrist_pitch_link.STL" />
      </geometry>
    </collision>
  </link>
  <joint
    name="left_wrist_pitch_joint"
    type="revolute">
    <origin
      xyz="0.1135 0 0"
      rpy="0 0 0" />
    <parent
      link="left_wrist_roll_link" />
    <child
      link="left_wrist_pitch_link" />
    <axis
      xyz="0 1 0" />
    <limit
      lower="-0.2736"
      upper="0.2736"
      effort="10.9250"
      velocity="3.1416" />
  </joint>
  <link
    name="left_wrist_yaw_link">
    <inertial>
      <origin
        xyz="0.033052 -0.000464 0.013883"
        rpy="0 0 0" />
      <mass
        value="0.044989" />
      <inertia
        ixx="0.000021"
        ixy="0"
        ixz="-0.000007"
        iyy="0.000029"
        iyz="0"
        izz="0.000023" />
    </inertial>
    <visual>
      <origin
        xyz="0 0 0"
        rpy="0 0 0" />
      <geometry>
        <mesh
          filename="./meshes/left_wrist_yaw_link.STL" />
      </geometry>
      <material
        name="">
        <color
          rgba="0.898039215686275 0.917647058823529 0.929411764705882 1" />
      </material>
    </visual>
    <collision>
      <origin
        xyz="0 0 0"
        rpy="0 0 0" />
      <geometry>
        <mesh
          filename="./meshes/left_wrist_yaw_link.STL" />
      </geometry>
    </collision>
  </link>
  <joint
    name="left_wrist_yaw_joint"
    type="revolute">
    <origin
      xyz="0.054 0 0"
      rpy="0 0 0" />
    <parent
      link="left_wrist_pitch_link" />
    <child
      link="left_wrist_yaw_link" />
    <axis
      xyz="0 0 1" />
    <limit
      lower="-0.6632"
      upper="0.6632"
      effort="10.9250"
      velocity="3.1416" />
  </joint>
  <link
    name="left_hand_link">
    <inertial>
      <origin
        xyz="0.0683645 -0.008132 0.010005"
        rpy="0 0 0" />
      <mass
        value="0.5" />
      <inertia
        ixx="0.000568"
        ixy="0.000080"
        ixz="-0.000136"
        iyy="0.001412"
        iyz="-0.000176"
        izz="0.001243" />
    </inertial>
    <visual>
      <origin
        xyz="0 0 0"
        rpy="0 0 0" />
      <geometry>
        <mesh
          filename="./meshes/left_hand_link.STL" />
      </geometry>
      <material
        name="">
        <color
          rgba="1 1 1 1" />
      </material>
    </visual>
    <collision>
      <origin
        xyz="0 0 0"
        rpy="0 0 0" />
      <geometry>
        <mesh
          filename="./meshes/left_hand_link.STL" />
      </geometry>
    </collision>
  </link>
  <joint
    name="left_hand_joint"
    type="fixed">
    <origin
      xyz="0.052 -0.001 0"
      rpy="0 0 0" />
    <parent
      link="left_wrist_yaw_link" />
    <child
      link="left_hand_link" />
    <axis
      xyz="0 0 0" />
  </joint>
  <link
    name="right_shoulder_pitch_link">
    <inertial>
      <origin
        xyz="0.005572 -0.0452205 -0.0000035"
        rpy="0 0 0" />
      <mass
        value="0.8091025" />
      <inertia
        ixx="0.0005705"
        ixy="-0.000002"
        ixz="0"
        iyy="0.0005635"
        iyz="0"
        izz="0.0005935" />
    </inertial>
    <visual>
      <origin
        xyz="0 0 0"
        rpy="0 0 0" />
      <geometry>
        <mesh
          filename="./meshes/right_shoulder_pitch_link.STL" />
      </geometry>
      <material
        name="">
        <color
          rgba="0.752941176470588 0.752941176470588 0.752941176470588 1" />
      </material>
    </visual>
    <collision>
      <origin
        xyz="0 0 0"
        rpy="0 0 0" />
      <geometry>
        <mesh
          filename="./meshes/right_shoulder_pitch_link.STL" />
      </geometry>
    </collision>
  </link>
  <joint
    name="right_shoulder_pitch_joint"
    type="revolute">
    <origin
      xyz="0 -0.1446 0.3935"
      rpy="0 0 0" />
    <parent
      link="torso_link" />
    <child
      link="right_shoulder_pitch_link" />
    <axis
      xyz="0 1 0" />
    <limit
      lower="-2.4871"
      upper="2.4871"
      effort="76"
      velocity="2.618" />
  </joint>
  <link
    name="right_shoulder_roll_link">
    <inertial>
      <origin
        xyz="0.004217 -0.000064 -0.097176"
        rpy="0 0 0" />
      <mass
        value="0.8873675" />
      <inertia
        ixx="0.0012865"
        ixy="0"
        ixz="0.000295"
        iyy="0.0014345"
        iyz="0"
        izz="0.000849" />
    </inertial>
    <visual>
      <origin
        xyz="0 0 0"
        rpy="0 0 0" />
      <geometry>
        <mesh
          filename="./meshes/right_shoulder_roll_link.STL" />
      </geometry>
      <material
        name="">
        <color
          rgba="0.752941176470588 0.752941176470588 0.752941176470588 1" />
      </material>
    </visual>
    <collision>
      <origin
        xyz="0 0 0"
        rpy="0 0 0" />
      <geometry>
        <mesh
          filename="./meshes/right_shoulder_roll_link.STL" />
      </geometry>
    </collision>
  </link>
  <joint
    name="right_shoulder_roll_joint"
    type="revolute">
    <origin
      xyz="0 -0.047 0"
      rpy="0 0 0" />
    <parent
      link="right_shoulder_pitch_link" />
    <child
      link="right_shoulder_roll_link" />
    <axis
      xyz="1 0 0" />
    <limit
      lower="-2.9016"
      upper="0"
      effort="76"
      velocity="2.618" />
  </joint>
  <link
    name="right_shoulder_yaw_link">
    <inertial>
      <origin
        xyz="0.0062655 -0.007667 -0.091717"
        rpy="0 0 0" />
      <mass
        value="0.9911815" />
      <inertia
        ixx="0.001378"
        ixy="-0.000009"
        ixz="-0.000067"
        iyy="0.001411"
        iyz="0.000075"
        izz="0.000788" />
    </inertial>
    <visual>
      <origin
        xyz="0 0 0"
        rpy="0 0 0" />
      <geometry>
        <mesh
          filename="./meshes/right_shoulder_yaw_link.STL" />
      </geometry>
      <material
        name="">
        <color
          rgba="0.752941176470588 0.752941176470588 0.752941176470588 1" />
      </material>
    </visual>
    <collision>
      <origin
        xyz="0 0 0"
        rpy="0 0 0" />
      <geometry>
        <mesh
          filename="./meshes/right_shoulder_yaw_link.STL" />
      </geometry>
    </collision>
  </link>
  <joint
    name="right_shoulder_yaw_joint"
    type="revolute">
    <origin
      xyz="-0.00072034 0 -0.1346"
      rpy="0 0 0" />
    <parent
      link="right_shoulder_roll_link" />
    <child
      link="right_shoulder_yaw_link" />
    <axis
      xyz="0 0 1" />
    <limit
      lower="-0.6629"
      upper="1.4915"
      effort="76"
      velocity="3.1416" />
  </joint>
  <link
    name="right_elbow_link">
    <inertial>
      <origin
        xyz="0.0811175 -0.0108235 -0.0084595"
        rpy="0 0 0" />
      <mass
        value="0.538791" />
      <inertia
        ixx="0.0003675"
        ixy="0.000202"
        ixz="-0.000025"
        iyy="0.0005905"
        iyz="-0.000010"
        izz="0.0007565" />
    </inertial>
    <visual>
      <origin
        xyz="0 0 0"
        rpy="0 0 0" />
      <geometry>
        <mesh
          filename="./meshes/right_elbow_link.STL" />
      </geometry>
      <material
        name="">
        <color
          rgba="0.752941176470588 0.752941176470588 0.752941176470588 1" />
      </material>
    </visual>
    <collision>
      <origin
        xyz="0 0 0"
        rpy="0 0 0" />
      <geometry>
        <mesh
          filename="./meshes/right_elbow_link.STL" />
      </geometry>
    </collision>
  </link>
  <joint
    name="right_elbow_joint"
    type="revolute">
    <origin
      xyz="0.0075 0 -0.1019"
      rpy="0 0 0" />
    <parent
      link="right_shoulder_yaw_link" />
    <child
      link="right_elbow_link" />
    <axis
      xyz="0 1 0" />
    <limit
      lower="-0.6632"
      upper="3.1503"
      effort="76"
      velocity="3.1416" />
  </joint>
  <link
    name="right_wrist_roll_link">
    <inertial>
      <origin
        xyz="0.0852865 -0.005134 -0.000046"
        rpy="0 0 0" />
      <mass
        value="0.679415" />
      <inertia
        ixx="0.0004425"
        ixy="-0.000098"
        ixz="-0.000001"
        iyy="0.001056"
        iyz="0"
        izz="0.001146" />
    </inertial>
    <visual>
      <origin
        xyz="0 0 0"
        rpy="0 0 0" />
      <geometry>
        <mesh
          filename="./meshes/right_wrist_roll_link.STL" />
      </geometry>
      <material
        name="">
        <color
          rgba="0.752941176470588 0.752941176470588 0.752941176470588 1" />
      </material>
    </visual>
    <collision>
      <origin
        xyz="0 0 0"
        rpy="0 0 0" />
      <geometry>
        <mesh
          filename="./meshes/right_wrist_roll_link.STL" />
      </geometry>
    </collision>
  </link>
  <joint
    name="right_wrist_roll_joint"
    type="revolute">
    <origin
      xyz="0.1 -0.0019 -0.009"
      rpy="0 0 0" />
    <parent
      link="right_elbow_link" />
    <child
      link="right_wrist_roll_link" />
    <axis
      xyz="1 0 0" />
    <limit
      lower="-2.4871"
      upper="2.4871"
      effort="10.9250"
      velocity="3.1416" />
  </joint>
  <link
    name="right_wrist_pitch_link">
    <inertial>
      <origin
        xyz="0.051473 -0.001913 0.006559"
        rpy="0 0 0" />
      <mass
        value="0.389479" />
      <inertia
        ixx="0.000146"
        ixy="0.000026"
        ixz="0.000007"
        iyy="0.000167"
        iyz="0.000005"
        izz="0.000187" />
    </inertial>
    <visual>
      <origin
        xyz="0 0 0"
        rpy="0 0 0" />
      <geometry>
        <mesh
          filename="./meshes/right_wrist_pitch_link.STL" />
      </geometry>
      <material
        name="">
        <color
          rgba="0.752941176470588 0.752941176470588 0.752941176470588 1" />
      </material>
    </visual>
    <collision>
      <origin
        xyz="0 0 0"
        rpy="0 0 0" />
      <geometry>
        <mesh
          filename="./meshes/right_wrist_pitch_link.STL" />
      </geometry>
    </collision>
  </link>
  <joint
    name="right_wrist_pitch_joint"
    type="revolute">
    <origin
      xyz="0.1135 0 0"
      rpy="0 0 0" />
    <parent
      link="right_wrist_roll_link" />
    <child
      link="right_wrist_pitch_link" />
    <axis
      xyz="0 1 0" />
    <limit
      lower="-0.2736"
      upper="0.2736"
      effort="10.9250"
      velocity="3.1416" />
  </joint>
  <link
    name="right_wrist_yaw_link">
    <inertial>
      <origin
        xyz="0.033052 0.000464 0.013883"
        rpy="0 0 0" />
      <mass
        value="0.044989" />
      <inertia
        ixx="2.1E-05"
        ixy="0"
        ixz="-0.000007"
        iyy="0.000029"
        iyz="0"
        izz="2.3E-05" />
    </inertial>
    <visual>
      <origin
        xyz="0 0 0"
        rpy="0 0 0" />
      <geometry>
        <mesh
          filename="./meshes/right_wrist_yaw_link.STL" />
      </geometry>
      <material
        name="">
        <color
          rgba="1 1 1 1" />
      </material>
    </visual>
    <collision>
      <origin
        xyz="0 0 0"
        rpy="0 0 0" />
      <geometry>
        <mesh
          filename="./meshes/right_wrist_yaw_link.STL" />
      </geometry>
    </collision>
  </link>
  <joint
    name="right_wrist_yaw_joint"
    type="revolute">
    <origin
      xyz="0.054 0 0"
      rpy="0 0 0" />
    <parent
      link="right_wrist_pitch_link" />
    <child
      link="right_wrist_yaw_link" />
    <axis
      xyz="0 0 1" />
    <limit
      lower="-0.6632"
      upper="0.6632"
      effort="10.9250"
      velocity="3.1416" />
  </joint>
  <link
    name="right_hand_link">
    <inertial>
      <origin
        xyz="0.0683645 0.008132 0.010005"
        rpy="0 0 0" />
      <mass
        value="0.5" />
      <inertia
        ixx="0.000568"
        ixy="-0.000080"
        ixz="-0.000136"
        iyy="0.001412"
        iyz="0.000176"
        izz="0.001243" />
    </inertial>
    <visual>
      <origin
        xyz="0 0 0"
        rpy="0 0 0" />
      <geometry>
        <mesh
          filename="./meshes/right_hand_link.STL" />
      </geometry>
      <material
        name="">
        <color
          rgba="1 1 1 1" />
      </material>
    </visual>
    <collision>
      <origin
        xyz="0 0 0"
        rpy="0 0 0" />
      <geometry>
        <mesh
          filename="./meshes/right_hand_link.STL" />
      </geometry>
    </collision>
  </link>
  <joint
    name="right_hand_joint"
    type="fixed">
    <origin
      xyz="0.052 0.001 0"
      rpy="0 0 0" />
    <parent
      link="right_wrist_yaw_link" />
    <child
      link="right_hand_link" />
    <axis
      xyz="0 0 0" />
  </joint>
  <link name="imu_link"></link>
  <joint
    name="imu_joint"
    type="fixed">
    <origin
      xyz="-0.09835 0 -0.052"
      rpy="0 0 0" />
    <parent
      link="base_link" />
    <child
      link="imu_link" />
    <axis
      xyz="0 0 0" />
  </joint>
</robot>